Workbook

Sheet EQUIPES
A1: FONTE VITACARE
C2: Proporção de gestantes com atendimento odontológico realizado nos últimos 12 meses
A3: UNIDADE | B3: 2026 | C3: JAN | D3: FEV | E3: MAR | F3: ABR | G3: MAI | H3: JUN | I3: JUL | J3: AGO | K3: SET | L3: OUT | M3: NOV | N3: DEZ | O3: 1 trim | P3: 2 trim | Q3: 3 trim | R3: 4 trim
A4: CF OFD | B4: =SUM(C18:N21)/SUM(C44:N47) -> 0.27530726 | C4: =(C$18+C$19+C$20+C$21)/(C$44+C$45+C$46+C$47) -> 0.31847134 | D4: =(D$18+D$19+D$20+D$21)/(D$44+D$45+D$46+D$47) -> 0.32769556 | E4: =(E$18+E$19+E$20+E$21)/(E$44+E$45+E$46+E$47) -> 0.29136691 | F4: =(F$18+F$19+F$20+F$21)/(F$44+F$45+F$46+F$47) -> 0.29061372 | G4: =IF((G$44+G$45+G$46+G$47)=0,"-",(G$18+G$19+G$20+G$21)/(G$44+G$45+G$46+G$47)) -> 0.24760383 | H4: =IF((H$44+H$45+H$46+H$47)=0,"-",(H$18+H$19+H$20+H$21)/(H$44+H$45+H$46+H$47)) -> 0.24273504 | I4: =IF((I$44+I$45+I$46+I$47)=0,"-",(I$18+I$19+I$20+I$21)/(I$44+I$45+I$46+I$47)) -> 0.26006711 | J4: =IF((J$44+J$45+J$46+J$47)=0,"-",(J$18+J$19+J$20+J$21)/(J$44+J$45+J$46+J$47)) -> 0.247557 | K4: =IF((K$44+K$45+K$46+K$47)=0,"-",(K$18+K$19+K$20+K$21)/(K$44+K$45+K$46+K$47)) -> - | L4: =IF((L$44+L$45+L$46+L$47)=0,"-",(L$18+L$19+L$20+L$21)/(L$44+L$45+L$46+L$47)) -> - | M4: =IF((M$44+M$45+M$46+M$47)=0,"-",(M$18+M$19+M$20+M$21)/(M$44+M$45+M$46+M$47)) -> - | N4: =IF((N$44+N$45+N$46+N$47)=0,"-",(N$18+N$19+N$20+N$21)/(N$44+N$45+N$46+N$47)) -> - | O4: =IF((O$44+O$45+O$46+O$47)=0,"0",(O$18+O$19+O$20+O$21)/(O$44+O$45+O$46+O$47)) -> 0.31133333 | P4: =IF((P$44+P$45+P$46+P$47)=0,"0",(P$18+P$19+P$20+P$21)/(P$44+P$45+P$46+P$47)) -> 0.25949008 | Q4: =IF((Q$44+Q$45+Q$46+Q$47)=0,"0",(Q$18+Q$19+Q$20+Q$21)/(Q$44+Q$45+Q$46+Q$47)) -> 0.25371901 | R4: =IF((R$44+R$45+R$46+R$47)=0,"0",(R$18+R$19+R$20+R$21)/(R$44+R$45+R$46+R$47)) -> 0
A5: CF RT | B5: =SUM(C22:N23)/SUM(C48:N49) -> 0.29967069 | C5: =(C$22+C$23)/(C$48+C$49) -> 0.27439024 | D5: =(D$22+D$23)/(D$48+D$49) -> 0.27596439 | E5: =(E$22+E$23)/(E$48+E$49) -> 0.27728614 | F5: =(F$22+F$23)/(F$48+F$49) -> 0.28571429 | G5: =IF((G$48+G$49)=0,"-",(G$22+G$23)/(G$48+G$49)) -> 0.3090379 | H5: =IF((H$48+H$49)=0,"-",(H$22+H$23)/(H$48+H$49)) -> 0.33333333 | I5: =IF((I$48+I$49)=0,"-",(I$22+I$23)/(I$48+I$49)) -> 0.31964809 | J5: =IF((J$48+J$49)=0,"-",(J$22+J$23)/(J$48+J$49)) -> 0.31920904 | K5: =IF((K$48+K$49)=0,"-",(K$22+K$23)/(K$48+K$49)) -> - | L5: =IF((L$48+L$49)=0,"-",(L$22+L$23)/(L$48+L$49)) -> - | M5: =IF((M$48+M$49)=0,"-",(M$22+M$23)/(M$48+M$49)) -> - | N5: =IF((N$48+N$49)=0,"-",(N$22+N$23)/(N$48+N$49)) -> - | O5: =IF((O$48+O$49)=0,"0",(O$22+O$23)/(O$48+O$49)) -> 0.27589641 | P5: =IF((P$48+P$49)=0,"0",(P$22+P$23)/(P$48+P$49)) -> 0.30947776 | Q5: =IF((Q$48+Q$49)=0,"0",(Q$22+Q$23)/(Q$48+Q$49)) -> 0.31942446 | R5: =IF((R$48+R$49)=0,"0",(R$22+R$23)/(R$48+R$49)) -> 0
A6: CMS CFF | B6: =SUM(C24:N25)/SUM(C50:N51) -> 0.31714049 | C6: =(C$24+C$25)/(C$50+C$51) -> 0.32167832 | D6: =(D$24+D$25)/(D$50+D$51) -> 0.31376975 | E6: =(E$24+E$25)/(E$50+E$51) -> 0.31848552 | F6: =(F$24+F$25)/(F$50+F$51) -> 0.31346578 | G6: =IF((G$50+G$51)=0,"-",(G$24+G$25)/(G$50+G$51)) -> 0.31140351 | H6: =IF((H$50+H$51)=0,"-",(H$24+H$25)/(H$50+H$51)) -> 0.31601732 | I6: =IF((I$50+I$51)=0,"-",(I$24+I$25)/(I$50+I$51)) -> 0.31956522 | J6: =IF((J$50+J$51)=0,"-",(J$24+J$25)/(J$50+J$51)) -> 0.32271762 | K6: =IF((K$50+K$51)=0,"-",(K$24+K$25)/(K$50+K$51)) -> - | L6: =IF((L$50+L$51)=0,"-",(L$24+L$25)/(L$50+L$51)) -> - | M6: =IF((M$50+M$51)=0,"-",(M$24+M$25)/(M$50+M$51)) -> - | N6: =IF((N$50+N$51)=0,"-",(N$24+N$25)/(N$50+N$51)) -> - | O6: =IF((O$50+O$51)=0,"0",(O$24+O$25)/(O$50+O$51)) -> 0.31794095 | P6: =IF((P$50+P$51)=0,"0",(P$24+P$25)/(P$50+P$51)) -> 0.31363968 | Q6: =IF((Q$50+Q$51)=0,"0",(Q$24+Q$25)/(Q$50+Q$51)) -> 0.32116004 | R6: =IF((R$50+R$51)=0,"0",(R$24+R$25)/(R$50+R$51)) -> 0
A7: CMS CB | B7: =SUM(C26:N26)/SUM(C52:N52) -> 0.22580645 | C7: =(C$26)/(C$52) -> 0.18064516 | D7: =(D$26)/(D$52) -> 0.19354839 | E7: =(E$26)/(E$52) -> 0.22012579 | F7: =(F$26)/(F$52) -> 0.21212121 | G7: =IF((G$52)=0,"-",(G$26)/(G$52)) -> 0.17901235 | H7: =IF((H$52)=0,"-",(H$26)/(H$52)) -> 0.23214286 | I7: =IF((I$52)=0,"-",(I$26)/(I$52)) -> 0.26785714 | J7: =IF((J$52)=0,"-",(J$26)/(J$52)) -> 0.31176471 | K7: =IF((K$52)=0,"-",(K$26)/(K$52)) -> - | L7: =IF((L$52)=0,"-",(L$26)/(L$52)) -> - | M7: =IF((M$52)=0,"-",(M$26)/(M$52)) -> - | N7: =IF((N$52)=0,"-",(N$26)/(N$52)) -> - | O7: =IF((O$52)=0,"0",(O$26)/(O$52)) -> 0.19829424 | P7: =IF((P$52)=0,"0",(P$26)/(P$52)) -> 0.20808081 | Q7: =IF((Q$52)=0,"0",(Q$26)/(Q$52)) -> 0.28994083 | R7: =IF((R$52)=0,"0",(R$26)/(R$52)) -> 0
A8: CMS HB | B8: =SUM(C27:N30)/SUM(C53:N56) -> 0.15549064 | C8: =(C$27+C$28+C$29+C$30)/(C$53+C$54+C$55+C$56) -> 0.17545748 | D8: =(D$27+D$28+D$29+D$30)/(D$53+D$54+D$55+D$56) -> 0.1629393 | E8: =(E$27+E$28+E$29+E$30)/(E$53+E$54+E$55+E$56) -> 0.16432432 | F8: =(F$27+F$28+F$29+F$30)/(F$53+F$54+F$55+F$56) -> 0.15671642 | G8: =IF((G$53+G$54+G$55+G$56)=0,"-",(G$27+G$28+G$29+G$30)/(G$53+G$54+G$55+G$56)) -> 0.15294118 | H8: =IF((H$53+H$54+H$55+H$56)=0,"-",(H$27+H$28+H$29+H$30)/(H$53+H$54+H$55+H$56)) -> 0.14631579 | I8: =IF((I$53+I$54+I$55+I$56)=0,"-",(I$27+I$28+I$29+I$30)/(I$53+I$54+I$55+I$56)) -> 0.14450262 | J8: =IF((J$53+J$54+J$55+J$56)=0,"-",(J$27+J$28+J$29+J$30)/(J$53+J$54+J$55+J$56)) -> 0.14166667 | K8: =IF((K$53+K$54+K$55+K$56)=0,"-",(K$27+K$28+K$29+K$30)/(K$53+K$54+K$55+K$56)) -> - | L8: =IF((L$53+L$54+L$55+L$56)=0,"-",(L$27+L$28+L$29+L$30)/(L$53+L$54+L$55+L$56)) -> - | M8: =IF((M$53+M$54+M$55+M$56)=0,"-",(M$27+M$28+M$29+M$30)/(M$53+M$54+M$55+M$56)) -> - | N8: =IF((N$53+N$54+N$55+N$56)=0,"-",(N$27+N$28+N$29+N$30)/(N$53+N$54+N$55+N$56)) -> - | O8: =IF((O$53+O$54+O$55+O$56)=0,"0",(O$27+O$28+O$29+O$30)/(O$53+O$54+O$55+O$56)) -> 0.16756176 | P8: =IF((P$53+P$54+P$55+P$56)=0,"0",(P$27+P$28+P$29+P$30)/(P$53+P$54+P$55+P$56)) -> 0.15196599 | Q8: =IF((Q$53+Q$54+Q$55+Q$56)=0,"0",(Q$27+Q$28+Q$29+Q$30)/(Q$53+Q$54+Q$55+Q$56)) -> 0.14308094 | R8: =IF((R$53+R$54+R$55+R$56)=0,"0",(R$27+R$28+R$29+R$30)/(R$53+R$54+R$55+R$56)) -> 0
A9: CMS HP | B9: =SUM(C31:N33)/SUM(C57:N59) -> 0.3971257 | C9: =(C$31+C$32+C$33)/(C$57+C$58+C$59) -> 0.44042232 | D9: =(D$31+D$32+D$33)/(D$57+D$58+D$59) -> 0.43941606 | E9: =(E$31+E$32+E$33)/(E$57+E$58+E$59) -> 0.43043478 | F9: =(F$31+F$32+F$33)/(F$57+F$58+F$59) -> 0.43043478 | G9: =IF((G$57+G$58+G$59)=0,"-",(G$31+G$32+G$33)/(G$57+G$58+G$59)) -> 0.38428571 | H9: =IF((H$57+H$58+H$59)=0,"-",(H$31+H$32+H$33)/(H$57+H$58+H$59)) -> 0.35693642 | I9: =IF((I$57+I$58+I$59)=0,"-",(I$31+I$32+I$33)/(I$57+I$58+I$59)) -> 0.34934498 | J9: =IF((J$57+J$58+J$59)=0,"-",(J$31+J$32+J$33)/(J$57+J$58+J$59)) -> 0.34782609 | K9: =IF((K$57+K$58+K$59)=0,"-",(K$31+K$32+K$33)/(K$57+K$58+K$59)) -> - | L9: =IF((L$57+L$58+L$59)=0,"-",(L$31+L$32+L$33)/(L$57+L$58+L$59)) -> - | M9: =IF((M$57+M$58+M$59)=0,"-",(M$31+M$32+M$33)/(M$57+M$58+M$59)) -> - | N9: =IF((N$57+N$58+N$59)=0,"-",(N$31+N$32+N$33)/(N$57+N$58+N$59)) -> - | O9: =IF((O$57+O$58+O$59)=0,"0",(O$31+O$32+O$33)/(O$57+O$58+O$59)) -> 0.43670265 | P9: =IF((P$57+P$58+P$59)=0,"0",(P$31+P$32+P$33)/(P$57+P$58+P$59)) -> 0.39048991 | Q9: =IF((Q$57+Q$58+Q$59)=0,"0",(Q$31+Q$32+Q$33)/(Q$57+Q$58+Q$59)) -> 0.34858388 | R9: =IF((R$57+R$58+R$59)=0,"0",(R$31+R$32+R$33)/(R$57+R$58+R$59)) -> 0
A10: CMS MAE | B10: =SUM(C34:N36)/SUM(C60:N62) -> 0.23178458 | C10: =(C$34+C$35+C$36)/(C$60+C$61+C$62) -> 0.22439759 | D10: =(D$34+D$35+D$36)/(D$60+D$61+D$62) -> 0.21837349 | E10: =(E$34+E$35+E$36)/(E$60+E$61+E$62) -> 0.21925926 | F10: =(F$34+F$35+F$36)/(F$60+F$61+F$62) -> 0.2244898 | G10: =IF((G$60+G$61+G$62)=0,"-",(G$34+G$35+G$36)/(G$60+G$61+G$62)) -> 0.23153409 | H10: =IF((H$60+H$61+H$62)=0,"-",(H$34+H$35+H$36)/(H$60+H$61+H$62)) -> 0.24309392 | I10: =IF((I$60+I$61+I$62)=0,"-",(I$34+I$35+I$36)/(I$60+I$61+I$62)) -> 0.24348958 | J10: =IF((J$60+J$61+J$62)=0,"-",(J$34+J$35+J$36)/(J$60+J$61+J$62)) -> 0.2446675 | K10: =IF((K$60+K$61+K$62)=0,"-",(K$34+K$35+K$36)/(K$60+K$61+K$62)) -> - | L10: =IF((L$60+L$61+L$62)=0,"-",(L$34+L$35+L$36)/(L$60+L$61+L$62)) -> - | M10: =IF((M$60+M$61+M$62)=0,"-",(M$34+M$35+M$36)/(M$60+M$61+M$62)) -> - | N10: =IF((N$60+N$61+N$62)=0,"-",(N$34+N$35+N$36)/(N$60+N$61+N$62)) -> - | O10: =IF((O$60+O$61+O$62)=0,"0",(O$34+O$35+O$36)/(O$60+O$61+O$62)) -> 0.220669 | P10: =IF((P$60+P$61+P$62)=0,"0",(P$34+P$35+P$36)/(P$60+P$61+P$62)) -> 0.23320719 | Q10: =IF((Q$60+Q$61+Q$62)=0,"0",(Q$34+Q$35+Q$36)/(Q$60+Q$61+Q$62)) -> 0.24408946 | R10: =IF((R$60+R$61+R$62)=0,"0",(R$34+R$35+R$36)/(R$60+R$61+R$62)) -> 0
A11: CMS NA | B11: =SUM(C37:N37)/SUM(C63:N63) -> 0.22743682 | C11: =(C$37)/(C$63) -> 0.16569767 | D11: =(D$37)/(D$63) -> 0.18181818 | E11: =(E$37)/(E$63) -> 0.21282799 | F11: =(F$37)/(F$63) -> 0.2228739 | G11: =IF((G$63)=0,"-",(G$37)/(G$63)) -> 0.24225352 | H11: =IF((H$63)=0,"-",(H$37)/(H$63)) -> 0.23235294 | I11: =IF((I$63)=0,"-",(I$37)/(I$63)) -> 0.26628895 | J11: =IF((J$63)=0,"-",(J$37)/(J$63)) -> 0.2917847 | K11: =IF((K$63)=0,"-",(K$37)/(K$63)) -> - | L11: =IF((L$63)=0,"-",(L$37)/(L$63)) -> - | M11: =IF((M$63)=0,"-",(M$37)/(M$63)) -> - | N11: =IF((N$63)=0,"-",(N$37)/(N$63)) -> - | O11: =IF((O$63)=0,"0",(O$37)/(O$63)) -> 0.18677043 | P11: =IF((P$63)=0,"0",(P$37)/(P$63)) -> 0.23262548 | Q11: =IF((Q$63)=0,"0",(Q$37)/(Q$63)) -> 0.27903683 | R11: =IF((R$63)=0,"0",(R$37)/(R$63)) -> 0
A12: CMS NR | B12: =SUM(C38:N38)/SUM(C64:N64) -> 0.31270358 | C12: =(C$38)/(C$64) -> 0.29081633 | D12: =(D$38)/(D$64) -> 0.29591837 | E12: =(E$38)/(E$64) -> 0.30964467 | F12: =(F$38)/(F$64) -> 0.29081633 | G12: =IF((G$64)=0,"-",(G$38)/(G$64)) -> 0.30890052 | H12: =IF((H$64)=0,"-",(H$38)/(H$64)) -> 0.32804233 | I12: =IF((I$64)=0,"-",(I$38)/(I$64)) -> 0.33510638 | J12: =IF((J$64)=0,"-",(J$38)/(J$64)) -> 0.34615385 | K12: =IF((K$64)=0,"-",(K$38)/(K$64)) -> - | L12: =IF((L$64)=0,"-",(L$38)/(L$64)) -> - | M12: =IF((M$64)=0,"-",(M$38)/(M$64)) -> - | N12: =IF((N$64)=0,"-",(N$38)/(N$64)) -> - | O12: =IF((O$64)=0,"0",(O$38)/(O$64)) -> 0.29881155 | P12: =IF((P$64)=0,"0",(P$38)/(P$64)) -> 0.30902778 | Q12: =IF((Q$64)=0,"0",(Q$38)/(Q$64)) -> 0.34054054 | R12: =IF((R$64)=0,"0",(R$38)/(R$64)) -> 0
A13: CAP 2.2 | B13: =SUM(C39:N39)/SUM(C65:N65) -> 0.26388415 | C13: =(C$39)/(C$65) -> 0.26896387 | D13: =(D$39)/(D$65) -> 0.26836759 | E13: =(E$39)/(E$65) -> 0.26886684 | F13: =(F$39)/(F$65) -> 0.26729272 | G13: =IF((G$65)=0,"-",(G$39)/(G$65)) -> 0.25760286 | H13: =IF((H$65)=0,"-",(H$39)/(H$65)) -> 0.25706595 | I13: =IF((I$65)=0,"-",(I$39)/(I$65)) -> 0.26085031 | J13: =IF((J$65)=0,"-",(J$39)/(J$65)) -> 0.26290569 | K13: =IF((K$65)=0,"-",(K$39)/(K$65)) -> - | L13: =IF((L$65)=0,"-",(L$39)/(L$65)) -> - | M13: =IF((M$65)=0,"-",(M$39)/(M$65)) -> - | N13: =IF((N$65)=0,"-",(N$39)/(N$65)) -> - | O13: =IF((O$65)=0,"0",(O$39)/(O$65)) -> 0.26873284 | P13: =IF((P$65)=0,"0",(P$39)/(P$65)) -> 0.26060469 | Q13: =IF((Q$65)=0,"0",(Q$39)/(Q$65)) -> 0.26188646 | R13: =IF((R$65)=0,"0",(R$39)/(R$65)) -> 0
A15: Numerador - atendidas pela odonto
C16: Numero de gestantes que passaram pela odonto antes do encerramento do pré natal
A17: UNIDADE | C17: JAN | D17: FEV | E17: MAR | F17: ABR | G17: MAI | H17: JUN | I17: JUL | J17: AGO | K17: SET | L17: OUT | M17: NOV | N17: DEZ | O17: 1 trim | P17: 2 trim | Q17: 3 trim | R17: 4 trim
A18: CF ODALEA FIRMO DUTRA | B18: ADOLFO CAMINHA ESB | C18: =SUMIF(jan!$A$1:$A$100,"ADOLFO CAMINHA",jan!$D$1:$D$100)+SUMIF(jan!$A$1:$A$100,"ITORORO",jan!$D$1:$D$100) -> 14 | D18: =SUMIF(fev!$A$1:$A$100,"ADOLFO CAMINHA",fev!$D$1:$D$100)+SUMIF(fev!$A$1:$A$100,"ITORORO",fev!$D$1:$D$100) -> 16 | E18: =SUMIF(mar!$A$1:$A$100,"ADOLFO CAMINHA",mar!$D$1:$D$100)+SUMIF(mar!$A$1:$A$100,"ITORORO",mar!$D$1:$D$100) -> 20 | F18: =SUMIF(abr!$A$1:$A$100,"ADOLFO CAMINHA",abr!$D$1:$D$100)+SUMIF(abr!$A$1:$A$100,"ITORORO",abr!$D$1:$D$100) -> 22 | G18: =SUMIF(mai!$A$1:$A$100,"ADOLFO CAMINHA",mai!$D$1:$D$100)+SUMIF(mai!$A$1:$A$100,"ITORORO",mai!$D$1:$D$100) -> 32 | H18: =SUMIF(jun!$A$1:$A$100,"ADOLFO CAMINHA",jun!$D$1:$D$100)+SUMIF(jun!$A$1:$A$100,"ITORORO",jun!$D$1:$D$100) -> 31 | I18: =SUMIF(jul!$A$1:$A$100,"ADOLFO CAMINHA",jul!$D$1:$D$100)+SUMIF(jul!$A$1:$A$100,"ITORORO",jul!$D$1:$D$100) -> 44 | J18: =SUMIF(ago!$A$1:$A$100,"ADOLFO CAMINHA",ago!$D$1:$D$100)+SUMIF(ago!$A$1:$A$100,"ITORORO",ago!$D$1:$D$100) -> 49 | K18: =SUMIF(set!$A$1:$A$100,"ADOLFO CAMINHA",set!$D$1:$D$100)+SUMIF(set!$A$1:$A$100,"ITORORO",set!$D$1:$D$100) -> 0 | L18: =SUMIF(out!$A$1:$A$100,"ADOLFO CAMINHA",out!$D$1:$D$100)+SUMIF(out!$A$1:$A$100,"ITORORO",out!$D$1:$D$100) -> 0 | M18: =SUMIF(nov!$A$1:$A$100,"ADOLFO CAMINHA",nov!$D$1:$D$100)+SUMIF(nov!$A$1:$A$100,"ITORORO",nov!$D$1:$D$100) -> 0 | N18: =SUMIF(dez!$A$1:$A$100,"ADOLFO CAMINHA",dez!$D$1:$D$100)+SUMIF(dez!$A$1:$A$100,"ITORORO",dez!$D$1:$D$100) -> 0 | O18: =C18+D18+E18 -> 50 | P18: =F18+G18+H18 -> 85 | Q18: =I18+J18+K18 -> 93 | R18: =L18+M18+N18 -> 0
B19: SANTO ESTEVAO ESB | C19: =SUMIF(jan!$A$1:$A$100,"SANTO ESTEVAO",jan!$D$1:$D$100)+SUMIF(jan!$A$1:$A$100,"GASTAO PENALVA I",jan!$D$1:$D$100)++SUMIF(jan!$A$1:$A$100,"GASTAO PENALVA II",jan!$D$1:$D$100) -> 68 | D19: =SUMIF(fev!$A$1:$A$100,"SANTO ESTEVAO",fev!$D$1:$D$100)+SUMIF(fev!$A$1:$A$100,"GASTAO PENALVA I",fev!$D$1:$D$100)++SUMIF(fev!$A$1:$A$100,"GASTAO PENALVA II",fev!$D$1:$D$100) -> 69 | E19: =SUMIF(mar!$A$1:$A$100,"SANTO ESTEVAO",mar!$D$1:$D$100)+SUMIF(mar!$A$1:$A$100,"GASTAO PENALVA I",mar!$D$1:$D$100)++SUMIF(mar!$A$1:$A$100,"GASTAO PENALVA II",mar!$D$1:$D$100) -> 79 | F19: =SUMIF(abr!$A$1:$A$100,"SANTO ESTEVAO",abr!$D$1:$D$100)+SUMIF(abr!$A$1:$A$100,"GASTAO PENALVA I",abr!$D$1:$D$100)++SUMIF(abr!$A$1:$A$100,"GASTAO PENALVA II",abr!$D$1:$D$100) -> 78 | G19: =SUMIF(mai!$A$1:$A$100,"SANTO ESTEVAO",mai!$D$1:$D$100)+SUMIF(mai!$A$1:$A$100,"GASTAO PENALVA I",mai!$D$1:$D$100)++SUMIF(mai!$A$1:$A$100,"GASTAO PENALVA II",mai!$D$1:$D$100) -> 59 | H19: =SUMIF(jun!$A$1:$A$100,"SANTO ESTEVAO",jun!$D$1:$D$100)+SUMIF(jun!$A$1:$A$100,"GASTAO PENALVA I",jun!$D$1:$D$100)++SUMIF(jun!$A$1:$A$100,"GASTAO PENALVA II",jun!$D$1:$D$100) -> 49 | I19: =SUMIF(jul!$A$1:$A$100,"SANTO ESTEVAO",jul!$D$1:$D$100)+SUMIF(jul!$A$1:$A$100,"GASTAO PENALVA I",jul!$D$1:$D$100)++SUMIF(jul!$A$1:$A$100,"GASTAO PENALVA II",jul!$D$1:$D$100) -> 51 | J19: =SUMIF(ago!$A$1:$A$100,"SANTO ESTEVAO",ago!$D$1:$D$100)+SUMIF(ago!$A$1:$A$100,"GASTAO PENALVA I",ago!$D$1:$D$100)++SUMIF(ago!$A$1:$A$100,"GASTAO PENALVA II",ago!$D$1:$D$100) -> 42 | K19: =SUMIF(set!$A$1:$A$100,"SANTO ESTEVAO",set!$D$1:$D$100)+SUMIF(set!$A$1:$A$100,"GASTAO PENALVA I",set!$D$1:$D$100)++SUMIF(set!$A$1:$A$100,"GASTAO PENALVA II",set!$D$1:$D$100) -> 0 | L19: =SUMIF(out!$A$1:$A$100,"SANTO ESTEVAO",out!$D$1:$D$100)+SUMIF(out!$A$1:$A$100,"GASTAO PENALVA I",out!$D$1:$D$100)++SUMIF(out!$A$1:$A$100,"GASTAO PENALVA II",out!$D$1:$D$100) -> 0 | M19: =SUMIF(nov!$A$1:$A$100,"SANTO ESTEVAO",nov!$D$1:$D$100)+SUMIF(nov!$A$1:$A$100,"GASTAO PENALVA I",nov!$D$1:$D$100)++SUMIF(nov!$A$1:$A$100,"GASTAO PENALVA II",nov!$D$1:$D$100) -> 0 | N19: =SUMIF(dez!$A$1:$A$100,"SANTO ESTEVAO",dez!$D$1:$D$100)+SUMIF(dez!$A$1:$A$100,"GASTAO PENALVA I",dez!$D$1:$D$100)++SUMIF(dez!$A$1:$A$100,"GASTAO PENALVA II",dez!$D$1:$D$100) -> 0 | O19: =C19+D19+E19 -> 216 | P19: =F19+G19+H19 -> 186 | Q19: =I19+J19+K19 -> 93 | R19: =L19+M19+N19 -> 0
B20: ARAXA ESB | C20: =SUMIF(jan!$A$1:$A$100,"ARAXA",jan!$D$1:$D$100)+SUMIF(jan!$A$1:$A$100,"UBERABA",jan!$D$1:$D$100) -> 39 | D20: =SUMIF(fev!$A$1:$A$100,"ARAXA",fev!$D$1:$D$100)+SUMIF(fev!$A$1:$A$100,"UBERABA",fev!$D$1:$D$100) -> 41 | E20: =SUMIF(mar!$A$1:$A$100,"ARAXA",mar!$D$1:$D$100)+SUMIF(mar!$A$1:$A$100,"UBERABA",mar!$D$1:$D$100) -> 35 | F20: =SUMIF(abr!$A$1:$A$100,"ARAXA",abr!$D$1:$D$100)+SUMIF(abr!$A$1:$A$100,"UBERABA",abr!$D$1:$D$100) -> 33 | G20: =SUMIF(mai!$A$1:$A$100,"ARAXA",mai!$D$1:$D$100)+SUMIF(mai!$A$1:$A$100,"UBERABA",mai!$D$1:$D$100) -> 37 | H20: =SUMIF(jun!$A$1:$A$100,"ARAXA",jun!$D$1:$D$100)+SUMIF(jun!$A$1:$A$100,"UBERABA",jun!$D$1:$D$100) -> 38 | I20: =SUMIF(jul!$A$1:$A$100,"ARAXA",jul!$D$1:$D$100)+SUMIF(jul!$A$1:$A$100,"UBERABA",jul!$D$1:$D$100) -> 36 | J20: =SUMIF(ago!$A$1:$A$100,"ARAXA",ago!$D$1:$D$100)+SUMIF(ago!$A$1:$A$100,"UBERABA",ago!$D$1:$D$100) -> 35 | K20: =SUMIF(set!$A$1:$A$100,"ARAXA",set!$D$1:$D$100)+SUMIF(set!$A$1:$A$100,"UBERABA",set!$D$1:$D$100) -> 0 | L20: =SUMIF(out!$A$1:$A$100,"ARAXA",out!$D$1:$D$100)+SUMIF(out!$A$1:$A$100,"UBERABA",out!$D$1:$D$100) -> 0 | M20: =SUMIF(nov!$A$1:$A$100,"ARAXA",nov!$D$1:$D$100)+SUMIF(nov!$A$1:$A$100,"UBERABA",nov!$D$1:$D$100) -> 0 | N20: =SUMIF(dez!$A$1:$A$100,"ARAXA",dez!$D$1:$D$100)+SUMIF(dez!$A$1:$A$100,"UBERABA",dez!$D$1:$D$100) -> 0 | O20: =C20+D20+E20 -> 115 | P20: =F20+G20+H20 -> 108 | Q20: =I20+J20+K20 -> 71 | R20: =L20+M20+N20 -> 0
B21: FURNAS ESB | C21: =SUMIF(jan!$A$1:$A$100,"FURNAS",jan!$D$1:$D$100)+SUMIF(jan!$A$1:$A$100,"ESPERANCA",jan!$D$1:$D$100) -> 29 | D21: =SUMIF(fev!$A$1:$A$100,"FURNAS",fev!$D$1:$D$100)+SUMIF(fev!$A$1:$A$100,"ESPERANCA",fev!$D$1:$D$100) -> 29 | E21: =SUMIF(mar!$A$1:$A$100,"FURNAS",mar!$D$1:$D$100)+SUMIF(mar!$A$1:$A$100,"ESPERANCA",mar!$D$1:$D$100) -> 28 | F21: =SUMIF(abr!$A$1:$A$100,"FURNAS",abr!$D$1:$D$100)+SUMIF(abr!$A$1:$A$100,"ESPERANCA",abr!$D$1:$D$100) -> 28 | G21: =SUMIF(mai!$A$1:$A$100,"FURNAS",mai!$D$1:$D$100)+SUMIF(mai!$A$1:$A$100,"ESPERANCA",mai!$D$1:$D$100) -> 27 | H21: =SUMIF(jun!$A$1:$A$100,"FURNAS",jun!$D$1:$D$100)+SUMIF(jun!$A$1:$A$100,"ESPERANCA",jun!$D$1:$D$100) -> 24 | I21: =SUMIF(jul!$A$1:$A$100,"FURNAS",jul!$D$1:$D$100)+SUMIF(jul!$A$1:$A$100,"ESPERANCA",jul!$D$1:$D$100) -> 24 | J21: =SUMIF(ago!$A$1:$A$100,"FURNAS",ago!$D$1:$D$100)+SUMIF(ago!$A$1:$A$100,"ESPERANCA",ago!$D$1:$D$100) -> 26 | K21: =SUMIF(set!$A$1:$A$100,"FURNAS",set!$D$1:$D$100)+SUMIF(set!$A$1:$A$100,"ESPERANCA",set!$D$1:$D$100) -> 0 | L21: =SUMIF(out!$A$1:$A$100,"FURNAS",out!$D$1:$D$100)+SUMIF(out!$A$1:$A$100,"ESPERANCA",out!$D$1:$D$100) -> 0 | M21: =SUMIF(nov!$A$1:$A$100,"FURNAS",nov!$D$1:$D$100)+SUMIF(nov!$A$1:$A$100,"ESPERANCA",nov!$D$1:$D$100) -> 0 | N21: =SUMIF(dez!$A$1:$A$100,"FURNAS",dez!$D$1:$D$100)+SUMIF(dez!$A$1:$A$100,"ESPERANCA",dez!$D$1:$D$100) -> 0 | O21: =C21+D21+E21 -> 86 | P21: =F21+G21+H21 -> 79 | Q21: =I21+J21+K21 -> 50 | R21: =L21+M21+N21 -> 0
A22: CF RECANTO DO TROVADOR | B22: POPULAR ESB | C22: =SUMIF(jan!$A$1:$A$100,"POPULAR",jan!$D$1:$D$100)+SUMIF(jan!$A$1:$A$100,"CARUARU",jan!$D$1:$D$100) -> 44 | D22: =SUMIF(fev!$A$1:$A$100,"POPULAR",fev!$D$1:$D$100)+SUMIF(fev!$A$1:$A$100,"CARUARU",fev!$D$1:$D$100) -> 46 | E22: =SUMIF(mar!$A$1:$A$100,"POPULAR",mar!$D$1:$D$100)+SUMIF(mar!$A$1:$A$100,"CARUARU",mar!$D$1:$D$100) -> 54 | F22: =SUMIF(abr!$A$1:$A$100,"POPULAR",abr!$D$1:$D$100)+SUMIF(abr!$A$1:$A$100,"CARUARU",abr!$D$1:$D$100) -> 55 | G22: =SUMIF(mai!$A$1:$A$100,"POPULAR",mai!$D$1:$D$100)+SUMIF(mai!$A$1:$A$100,"CARUARU",mai!$D$1:$D$100) -> 62 | H22: =SUMIF(jun!$A$1:$A$100,"POPULAR",jun!$D$1:$D$100)+SUMIF(jun!$A$1:$A$100,"CARUARU",jun!$D$1:$D$100) -> 67 | I22: =SUMIF(jul!$A$1:$A$100,"POPULAR",jul!$D$1:$D$100)+SUMIF(jul!$A$1:$A$100,"CARUARU",jul!$D$1:$D$100) -> 64 | J22: =SUMIF(ago!$A$1:$A$100,"POPULAR",ago!$D$1:$D$100)+SUMIF(ago!$A$1:$A$100,"CARUARU",ago!$D$1:$D$100) -> 69 | K22: =SUMIF(set!$A$1:$A$100,"POPULAR",set!$D$1:$D$100)+SUMIF(set!$A$1:$A$100,"CARUARU",set!$D$1:$D$100) -> 0 | L22: =SUMIF(out!$A$1:$A$100,"POPULAR",out!$D$1:$D$100)+SUMIF(out!$A$1:$A$100,"CARUARU",out!$D$1:$D$100) -> 0 | M22: =SUMIF(nov!$A$1:$A$100,"POPULAR",nov!$D$1:$D$100)+SUMIF(nov!$A$1:$A$100,"CARUARU",nov!$D$1:$D$100) -> 0 | N22: =SUMIF(dez!$A$1:$A$100,"POPULAR",dez!$D$1:$D$100)+SUMIF(dez!$A$1:$A$100,"CARUARU",dez!$D$1:$D$100) -> 0 | O22: =C22+D22+E22 -> 144 | P22: =F22+G22+H22 -> 184 | Q22: =I22+J22+K22 -> 133 | R22: =L22+M22+N22 -> 0
B23: MARTINHO DA VILA ESB | C23: =SUMIF(jan!$A$1:$A$100,"MARTINHO DA VILA",jan!$D$1:$D$100)+SUMIF(jan!$A$1:$A$100,"NOEL ROSA",jan!$D$1:$D$100) -> 46 | D23: =SUMIF(fev!$A$1:$A$100,"MARTINHO DA VILA",fev!$D$1:$D$100)+SUMIF(fev!$A$1:$A$100,"NOEL ROSA",fev!$D$1:$D$100) -> 47 | E23: =SUMIF(mar!$A$1:$A$100,"MARTINHO DA VILA",mar!$D$1:$D$100)+SUMIF(mar!$A$1:$A$100,"NOEL ROSA",mar!$D$1:$D$100) -> 40 | F23: =SUMIF(abr!$A$1:$A$100,"MARTINHO DA VILA",abr!$D$1:$D$100)+SUMIF(abr!$A$1:$A$100,"NOEL ROSA",abr!$D$1:$D$100) -> 43 | G23: =SUMIF(mai!$A$1:$A$100,"MARTINHO DA VILA",mai!$D$1:$D$100)+SUMIF(mai!$A$1:$A$100,"NOEL ROSA",mai!$D$1:$D$100) -> 44 | H23: =SUMIF(jun!$A$1:$A$100,"MARTINHO DA VILA",jun!$D$1:$D$100)+SUMIF(jun!$A$1:$A$100,"NOEL ROSA",jun!$D$1:$D$100) -> 49 | I23: =SUMIF(jul!$A$1:$A$100,"MARTINHO DA VILA",jul!$D$1:$D$100)+SUMIF(jul!$A$1:$A$100,"NOEL ROSA",jul!$D$1:$D$100) -> 45 | J23: =SUMIF(ago!$A$1:$A$100,"MARTINHO DA VILA",ago!$D$1:$D$100)+SUMIF(ago!$A$1:$A$100,"NOEL ROSA",ago!$D$1:$D$100) -> 44 | K23: =SUMIF(set!$A$1:$A$100,"MARTINHO DA VILA",set!$D$1:$D$100)+SUMIF(set!$A$1:$A$100,"NOEL ROSA",set!$D$1:$D$100) -> 0 | L23: =SUMIF(out!$A$1:$A$100,"MARTINHO DA VILA",out!$D$1:$D$100)+SUMIF(out!$A$1:$A$100,"NOEL ROSA",out!$D$1:$D$100) -> 0 | M23: =SUMIF(nov!$A$1:$A$100,"MARTINHO DA VILA",nov!$D$1:$D$100)+SUMIF(nov!$A$1:$A$100,"NOEL ROSA",nov!$D$1:$D$100) -> 0 | N23: =SUMIF(dez!$A$1:$A$100,"MARTINHO DA VILA",dez!$D$1:$D$100)+SUMIF(dez!$A$1:$A$100,"NOEL ROSA",dez!$D$1:$D$100) -> 0 | O23: =C23+D23+E23 -> 133 | P23: =F23+G23+H23 -> 136 | Q23: =I23+J23+K23 -> 89 | R23: =L23+M23+N23 -> 0
A24: CMS CARLOS FIGUEIREDO FILHO | B24: TERREIRAO ESB | C24: =SUMIF(jan!$A$1:$A$100,"LADEIRA DO MOREIRA",jan!$D$1:$D$100)/2+SUMIF(jan!$A$1:$A$100,"TERREIRAO",jan!$D$1:$D$100) -> 59.5 | D24: =SUMIF(fev!$A$1:$A$100,"LADEIRA DO MOREIRA",fev!$D$1:$D$100)/2+SUMIF(fev!$A$1:$A$100,"TERREIRAO",fev!$D$1:$D$100) -> 57.5 | E24: =SUMIF(mar!$A$1:$A$100,"LADEIRA DO MOREIRA",mar!$D$1:$D$100)/2+SUMIF(mar!$A$1:$A$100,"TERREIRAO",mar!$D$1:$D$100) -> 60 | F24: =SUMIF(abr!$A$1:$A$100,"LADEIRA DO MOREIRA",abr!$D$1:$D$100)/2+SUMIF(abr!$A$1:$A$100,"TERREIRAO",abr!$D$1:$D$100) -> 58 | G24: =SUMIF(mai!$A$1:$A$100,"LADEIRA DO MOREIRA",mai!$D$1:$D$100)/2+SUMIF(mai!$A$1:$A$100,"TERREIRAO",mai!$D$1:$D$100) -> 57 | H24: =SUMIF(jun!$A$1:$A$100,"LADEIRA DO MOREIRA",jun!$D$1:$D$100)/2+SUMIF(jun!$A$1:$A$100,"TERREIRAO",jun!$D$1:$D$100) -> 60 | I24: =SUMIF(jul!$A$1:$A$100,"LADEIRA DO MOREIRA",jul!$D$1:$D$100)/2+SUMIF(jul!$A$1:$A$100,"TERREIRAO",jul!$D$1:$D$100) -> 58.5 | J24: =SUMIF(ago!$A$1:$A$100,"LADEIRA DO MOREIRA",ago!$D$1:$D$100)/2+SUMIF(ago!$A$1:$A$100,"TERREIRAO",ago!$D$1:$D$100) -> 62 | K24: =SUMIF(set!$A$1:$A$100,"LADEIRA DO MOREIRA",set!$D$1:$D$100)/2+SUMIF(set!$A$1:$A$100,"TERREIRAO",set!$D$1:$D$100) -> 0 | L24: =SUMIF(out!$A$1:$A$100,"LADEIRA DO MOREIRA",out!$D$1:$D$100)/2+SUMIF(out!$A$1:$A$100,"TERREIRAO",out!$D$1:$D$100) -> 0 | M24: =SUMIF(nov!$A$1:$A$100,"LADEIRA DO MOREIRA",nov!$D$1:$D$100)/2+SUMIF(nov!$A$1:$A$100,"TERREIRAO",nov!$D$1:$D$100) -> 0 | N24: =SUMIF(dez!$A$1:$A$100,"LADEIRA DO MOREIRA",dez!$D$1:$D$100)/2+SUMIF(dez!$A$1:$A$100,"TERREIRAO",dez!$D$1:$D$100) -> 0 | O24: =C24+D24+E24 -> 177 | P24: =F24+G24+H24 -> 175 | Q24: =I24+J24+K24 -> 120.5 | R24: =L24+M24+N24 -> 0
B25: SEMENTE ESB | C25: =SUMIF(jan!$A$1:$A$100,"LADEIRA DO MOREIRA",jan!$D$1:$D$100)/2+SUMIF(jan!$A$1:$A$100,"SEMENTE",jan!$D$1:$D$100) -> 78.5 | D25: =SUMIF(fev!$A$1:$A$100,"LADEIRA DO MOREIRA",fev!$D$1:$D$100)/2+SUMIF(fev!$A$1:$A$100,"SEMENTE",fev!$D$1:$D$100) -> 81.5 | E25: =SUMIF(mar!$A$1:$A$100,"LADEIRA DO MOREIRA",mar!$D$1:$D$100)/2+SUMIF(mar!$A$1:$A$100,"SEMENTE",mar!$D$1:$D$100) -> 83 | F25: =SUMIF(abr!$A$1:$A$100,"LADEIRA DO MOREIRA",abr!$D$1:$D$100)/2+SUMIF(abr!$A$1:$A$100,"SEMENTE",abr!$D$1:$D$100) -> 84 | G25: =SUMIF(mai!$A$1:$A$100,"LADEIRA DO MOREIRA",mai!$D$1:$D$100)/2+SUMIF(mai!$A$1:$A$100,"SEMENTE",mai!$D$1:$D$100) -> 85 | H25: =SUMIF(jun!$A$1:$A$100,"LADEIRA DO MOREIRA",jun!$D$1:$D$100)/2+SUMIF(jun!$A$1:$A$100,"SEMENTE",jun!$D$1:$D$100) -> 86 | I25: =SUMIF(jul!$A$1:$A$100,"LADEIRA DO MOREIRA",jul!$D$1:$D$100)/2+SUMIF(jul!$A$1:$A$100,"SEMENTE",jul!$D$1:$D$100) -> 88.5 | J25: =SUMIF(ago!$A$1:$A$100,"LADEIRA DO MOREIRA",ago!$D$1:$D$100)/2+SUMIF(ago!$A$1:$A$100,"SEMENTE",ago!$D$1:$D$100) -> 90 | K25: =SUMIF(set!$A$1:$A$100,"LADEIRA DO MOREIRA",set!$D$1:$D$100)/2+SUMIF(set!$A$1:$A$100,"SEMENTE",set!$D$1:$D$100) -> 0 | L25: =SUMIF(out!$A$1:$A$100,"LADEIRA DO MOREIRA",out!$D$1:$D$100)/2+SUMIF(out!$A$1:$A$100,"SEMENTE",out!$D$1:$D$100) -> 0 | M25: =SUMIF(nov!$A$1:$A$100,"LADEIRA DO MOREIRA",nov!$D$1:$D$100)/2+SUMIF(nov!$A$1:$A$100,"SEMENTE",nov!$D$1:$D$100) -> 0 | N25: =SUMIF(dez!$A$1:$A$100,"LADEIRA DO MOREIRA",dez!$D$1:$D$100)/2+SUMIF(dez!$A$1:$A$100,"SEMENTE",dez!$D$1:$D$100) -> 0 | O25: =C25+D25+E25 -> 243 | P25: =F25+G25+H25 -> 255 | Q25: =I25+J25+K25 -> 178.5 | R25: =L25+M25+N25 -> 0
A26: CMS CASA BRANCA | B26: CASA BRANCA ESB | C26: =SUMIF(jan!$A$1:$A$100,"CASA BRANCA",jan!$D$1:$D$100)+SUMIF(jan!$A$1:$A$100,"CHACARA DO CEU",jan!$D$1:$D$100) -> 28 | D26: =SUMIF(fev!$A$1:$A$100,"CASA BRANCA",fev!$D$1:$D$100)+SUMIF(fev!$A$1:$A$100,"CHACARA DO CEU",fev!$D$1:$D$100) -> 30 | E26: =SUMIF(mar!$A$1:$A$100,"CASA BRANCA",mar!$D$1:$D$100)+SUMIF(mar!$A$1:$A$100,"CHACARA DO CEU",mar!$D$1:$D$100) -> 35 | F26: =SUMIF(abr!$A$1:$A$100,"CASA BRANCA",abr!$D$1:$D$100)+SUMIF(abr!$A$1:$A$100,"CHACARA DO CEU",abr!$D$1:$D$100) -> 35 | G26: =SUMIF(mai!$A$1:$A$100,"CASA BRANCA",mai!$D$1:$D$100)+SUMIF(mai!$A$1:$A$100,"CHACARA DO CEU",mai!$D$1:$D$100) -> 29 | H26: =SUMIF(jun!$A$1:$A$100,"CASA BRANCA",jun!$D$1:$D$100)+SUMIF(jun!$A$1:$A$100,"CHACARA DO CEU",jun!$D$1:$D$100) -> 39 | I26: =SUMIF(jul!$A$1:$A$100,"CASA BRANCA",jul!$D$1:$D$100)+SUMIF(jul!$A$1:$A$100,"CHACARA DO CEU",jul!$D$1:$D$100) -> 45 | J26: =SUMIF(ago!$A$1:$A$100,"CASA BRANCA",ago!$D$1:$D$100)+SUMIF(ago!$A$1:$A$100,"CHACARA DO CEU",ago!$D$1:$D$100) -> 53 | K26: =SUMIF(set!$A$1:$A$100,"CASA BRANCA",set!$D$1:$D$100)+SUMIF(set!$A$1:$A$100,"CHACARA DO CEU",set!$D$1:$D$100) -> 0 | L26: =SUMIF(out!$A$1:$A$100,"CASA BRANCA",out!$D$1:$D$100)+SUMIF(out!$A$1:$A$100,"CHACARA DO CEU",out!$D$1:$D$100) -> 0 | M26: =SUMIF(nov!$A$1:$A$100,"CASA BRANCA",nov!$D$1:$D$100)+SUMIF(nov!$A$1:$A$100,"CHACARA DO CEU",nov!$D$1:$D$100) -> 0 | N26: =SUMIF(dez!$A$1:$A$100,"CASA BRANCA",dez!$D$1:$D$100)+SUMIF(dez!$A$1:$A$100,"CHACARA DO CEU",dez!$D$1:$D$100) -> 0 | O26: =C26+D26+E26 -> 93 | P26: =F26+G26+H26 -> 103 | Q26: =I26+J26+K26 -> 98 | R26: =L26+M26+N26 -> 0
A27: CMS HEITOR BELTRÃO | B27: SALGUEIRO ESB | C27: =SUMIF(jan!$A$1:$A$94,"SALGUEIRO",jan!$D$1:$D$100)+SUMIF(jan!$A$1:$A$94,"PRACA VARNHAGEM",jan!$D$1:$D$100)+SUMIF(jan!$A$1:$A$94,"RAIZES DO SALGUEIRO ESF",jan!$D$1:$D$100) -> 83 | D27: =SUMIF(fev!$A$1:$A$100,"SALGUEIRO",fev!$D$1:$D$100)+SUMIF(fev!$A$1:$A$100,"PRACA VARNHAGEM",fev!$D$1:$D$100)+SUMIF(fev!$A$1:$A$100,"RAIZES DO SALGUEIRO ESF",fev!$D$1:$D$100) -> 79 | E27: =SUMIF(mar!$A$1:$A$100,"SALGUEIRO",mar!$D$1:$D$100)+SUMIF(mar!$A$1:$A$100,"PRACA VARNHAGEM",mar!$D$1:$D$100)+SUMIF(mar!$A$1:$A$100,"RAIZES DO SALGUEIRO ESF",mar!$D$1:$D$100) -> 82 | F27: =SUMIF(abr!$A$1:$A$100,"SALGUEIRO",abr!$D$1:$D$100)+SUMIF(abr!$A$1:$A$100,"PRACA VARNHAGEM",abr!$D$1:$D$100)+SUMIF(abr!$A$1:$A$100,"RAIZES DO SALGUEIRO ESF",abr!$D$1:$D$100) -> 78 | G27: =SUMIF(mai!$A$1:$A$100,"SALGUEIRO",mai!$D$1:$D$100)+SUMIF(mai!$A$1:$A$100,"PRACA VARNHAGEM",mai!$D$1:$D$100)+SUMIF(mai!$A$1:$A$100,"RAIZES DO SALGUEIRO ESF",mai!$D$1:$D$100) -> 77 | H27: =SUMIF(jun!$A$1:$A$100,"SALGUEIRO",jun!$D$1:$D$100)+SUMIF(jun!$A$1:$A$100,"PRACA VARNHAGEM",jun!$D$1:$D$100)+SUMIF(jun!$A$1:$A$100,"RAIZES DO SALGUEIRO ESF",jun!$D$1:$D$100) -> 71 | I27: =SUMIF(jul!$A$1:$A$100,"SALGUEIRO",jul!$D$1:$D$100)+SUMIF(jul!$A$1:$A$100,"PRACA VARNHAGEM",jul!$D$1:$D$100)+SUMIF(jul!$A$1:$A$100,"RAIZES DO SALGUEIRO ESF",jul!$D$1:$D$100) -> 72 | J27: =SUMIF(ago!$A$1:$A$100,"SALGUEIRO",ago!$D$1:$D$100)+SUMIF(ago!$A$1:$A$100,"PRACA VARNHAGEM",ago!$D$1:$D$100)+SUMIF(ago!$A$1:$A$100,"RAIZES DO SALGUEIRO ESF",ago!$D$1:$D$100) -> 68 | K27: =SUMIF(set!$A$1:$A$100,"SALGUEIRO",set!$D$1:$D$100)+SUMIF(set!$A$1:$A$100,"PRACA VARNHAGEM",set!$D$1:$D$100)+SUMIF(set!$A$1:$A$100,"RAIZES DO SALGUEIRO ESF",set!$D$1:$D$100) -> 0 | L27: =SUMIF(out!$A$1:$A$100,"SALGUEIRO",out!$D$1:$D$100)+SUMIF(out!$A$1:$A$100,"PRACA VARNHAGEM",out!$D$1:$D$100)+SUMIF(out!$A$1:$A$100,"RAIZES DO SALGUEIRO ESF",out!$D$1:$D$100) -> 0 | M27: =SUMIF(nov!$A$1:$A$100,"SALGUEIRO",nov!$D$1:$D$100)+SUMIF(nov!$A$1:$A$100,"PRACA VARNHAGEM",nov!$D$1:$D$100)+SUMIF(nov!$A$1:$A$100,"RAIZES DO SALGUEIRO ESF",nov!$D$1:$D$100) -> 0 | N27: =SUMIF(dez!$A$1:$A$100,"SALGUEIRO",dez!$D$1:$D$100)+SUMIF(dez!$A$1:$A$100,"PRACA VARNHAGEM",dez!$D$1:$D$100)+SUMIF(dez!$A$1:$A$100,"RAIZES DO SALGUEIRO ESF",dez!$D$1:$D$100) -> 0 | O27: =C27+D27+E27 -> 244 | P27: =F27+G27+H27 -> 226 | Q27: =I27+J27+K27 -> 140 | R27: =L27+M27+N27 -> 0 | S27: =C27+D27+E27 -> 244
B28: BARAO DE PIRASSINUNGA ESB | C28: =SUMIF(jan!$A$1:$A$94,"BARAO DE PIRASSINUNGA",jan!$D$1:$D$100)+SUMIF(jan!$A$1:$A$94,"ANTONIO BASILIO ESF",jan!$D$1:$D$100)+SUMIF(jan!$A$1:$A$94,"SANTA SOFIA",jan!$D$1:$D$100)+SUMIF(jan!$A$1:$A$94,"SAO FRANCISCO I",jan!$D$1:$D$100)+SUMIF(jan!$A$1:$A$94,"SAO FRANCISCO II",jan!$D$1:$D$100)+SUMIF(jan!$A$1:$A$94,"SAO FRANCISCO III",jan!$D$1:$D$100) -> 25 | D28: =SUMIF(fev!$A$1:$A$100,"BARAO DE PIRASSINUNGA",fev!$D$1:$D$100)+SUMIF(fev!$A$1:$A$100,"ANTONIO BASILIO ESF",fev!$D$1:$D$100)+SUMIF(fev!$A$1:$A$100,"SANTA SOFIA",fev!$D$1:$D$100)+SUMIF(fev!$A$1:$A$100,"SAO FRANCISCO I **",fev!$D$1:$D$100) -> 20 | E28: =SUMIF(mar!$A$1:$A$100,"BARAO DE PIRASSINUNGA",mar!$D$1:$D$100)+SUMIF(mar!$A$1:$A$100,"ANTONIO BASILIO ESF",mar!$D$1:$D$100)+SUMIF(mar!$A$1:$A$100,"SANTA SOFIA",mar!$D$1:$D$100)+SUMIF(mar!$A$1:$A$100,"SAO FRANCISCO I **",mar!$D$1:$D$100) -> 20 | F28: =SUMIF(abr!$A$1:$A$100,"BARAO DE PIRASSINUNGA",abr!$D$1:$D$100)+SUMIF(abr!$A$1:$A$100,"ANTONIO BASILIO ESF",abr!$D$1:$D$100)+SUMIF(abr!$A$1:$A$100,"SANTA SOFIA",abr!$D$1:$D$100)+SUMIF(abr!$A$1:$A$100,"SAO FRANCISCO I **",abr!$D$1:$D$100) -> 24 | G28: =SUMIF(mai!$A$1:$A$100,"BARAO DE PIRASSINUNGA",mai!$D$1:$D$100)+SUMIF(mai!$A$1:$A$100,"ANTONIO BASILIO ESF",mai!$D$1:$D$100)+SUMIF(mai!$A$1:$A$100,"SANTA SOFIA",mai!$D$1:$D$100)+SUMIF(mai!$A$1:$A$100,"SAO FRANCISCO I **",mai!$D$1:$D$100) -> 26 | H28: =SUMIF(jun!$A$1:$A$100,"BARAO DE PIRASSINUNGA",jun!$D$1:$D$100)+SUMIF(jun!$A$1:$A$100,"ANTONIO BASILIO ESF",jun!$D$1:$D$100)+SUMIF(jun!$A$1:$A$100,"SANTA SOFIA",jun!$D$1:$D$100)+SUMIF(jun!$A$1:$A$100,"SAO FRANCISCO I **",jun!$D$1:$D$100) -> 27 | I28: =SUMIF(jul!$A$1:$A$100,"BARAO DE PIRASSINUNGA",jul!$D$1:$D$100)+SUMIF(jul!$A$1:$A$100,"ANTONIO BASILIO ESF",jul!$D$1:$D$100)+SUMIF(jul!$A$1:$A$100,"SANTA SOFIA",jul!$D$1:$D$100)+SUMIF(jul!$A$1:$A$100,"SAO FRANCISCO I **",jul!$D$1:$D$100) -> 23 | J28: =SUMIF(ago!$A$1:$A$100,"BARAO DE PIRASSINUNGA",ago!$D$1:$D$100)+SUMIF(ago!$A$1:$A$100,"ANTONIO BASILIO ESF",ago!$D$1:$D$100)+SUMIF(ago!$A$1:$A$100,"SANTA SOFIA",ago!$D$1:$D$100)+SUMIF(ago!$A$1:$A$100,"SAO FRANCISCO I **",ago!$D$1:$D$100) -> 22 | K28: =SUMIF(set!$A$1:$A$100,"BARAO DE PIRASSINUNGA",set!$D$1:$D$100)+SUMIF(set!$A$1:$A$100,"ANTONIO BASILIO ESF",set!$D$1:$D$100)+SUMIF(set!$A$1:$A$100,"SANTA SOFIA",set!$D$1:$D$100)+SUMIF(set!$A$1:$A$100,"SAO FRANCISCO I **",set!$D$1:$D$100) -> 0 | L28: =SUMIF(out!$A$1:$A$100,"BARAO DE PIRASSINUNGA",out!$D$1:$D$100)+SUMIF(out!$A$1:$A$100,"ANTONIO BASILIO ESF",out!$D$1:$D$100)+SUMIF(out!$A$1:$A$100,"SANTA SOFIA",out!$D$1:$D$100)+SUMIF(out!$A$1:$A$100,"SAO FRANCISCO I **",out!$D$1:$D$100) -> 0 | M28: =SUMIF(nov!$A$1:$A$100,"BARAO DE PIRASSINUNGA",nov!$D$1:$D$100)+SUMIF(nov!$A$1:$A$100,"ANTONIO BASILIO ESF",nov!$D$1:$D$100)+SUMIF(nov!$A$1:$A$100,"SANTA SOFIA",nov!$D$1:$D$100)+SUMIF(nov!$A$1:$A$100,"SAO FRANCISCO I **",nov!$D$1:$D$100) -> 0 | N28: =SUMIF(dez!$A$1:$A$100,"BARAO DE PIRASSINUNGA",dez!$D$1:$D$100)+SUMIF(dez!$A$1:$A$100,"ANTONIO BASILIO ESF",dez!$D$1:$D$100)+SUMIF(dez!$A$1:$A$100,"SANTA SOFIA",dez!$D$1:$D$100)+SUMIF(dez!$A$1:$A$100,"SAO FRANCISCO I **",dez!$D$1:$D$100) -> 0 | O28: =C28+D28+E28 -> 65 | P28: =F28+G28+H28 -> 77 | Q28: =I28+J28+K28 -> 45 | R28: =L28+M28+N28 -> 0 | S28: =C28+D28+E28 -> 65
B29: CATRAMBI ESB | C29: =SUMIF(jan!$A$1:$A$94,"CATRAMBI I",jan!$D$1:$D$100)+SUMIF(jan!$A$1:$A$94,"CATRAMBI II",jan!$D$1:$D$100)+SUMIF(jan!$A$1:$A$94,"CATRAMBI III",jan!$D$1:$D$100)+SUMIF(jan!$A$1:$A$94,"PINHEIRO DA CUNHA ESF",jan!$D$1:$D$100)+SUMIF(jan!$A$1:$A$94,"ALZIRA BRANDAO",jan!$D$1:$D$100)+SUMIF(jan!$A$1:$A$94,"DONA DELFINA",jan!$D$1:$D$100) -> 34 | D29: =SUMIF(fev!$A$1:$A$100,"CATRAMBI I **",fev!$D$1:$D$100)+SUMIF(fev!$A$1:$A$100,"PINHEIRO DA CUNHA ESF",fev!$D$1:$D$100)+SUMIF(fev!$A$1:$A$100,"ALZIRA BRANDAO",fev!$D$1:$D$100)+SUMIF(fev!$A$1:$A$100,"DONA DELFINA",fev!$D$1:$D$100) -> 33 | E29: =SUMIF(mar!$A$1:$A$100,"CATRAMBI I **",mar!$D$1:$D$100)+SUMIF(mar!$A$1:$A$100,"PINHEIRO DA CUNHA ESF",mar!$D$1:$D$100)+SUMIF(mar!$A$1:$A$100,"ALZIRA BRANDAO",mar!$D$1:$D$100)+SUMIF(mar!$A$1:$A$100,"DONA DELFINA",mar!$D$1:$D$100) -> 29 | F29: =SUMIF(abr!$A$1:$A$100,"CATRAMBI I **",abr!$D$1:$D$100)+SUMIF(abr!$A$1:$A$100,"PINHEIRO DA CUNHA ESF",abr!$D$1:$D$100)+SUMIF(abr!$A$1:$A$100,"ALZIRA BRANDAO",abr!$D$1:$D$100)+SUMIF(abr!$A$1:$A$100,"DONA DELFINA",abr!$D$1:$D$100) -> 22 | G29: =SUMIF(mai!$A$1:$A$100,"CATRAMBI I **",mai!$D$1:$D$100)+SUMIF(mai!$A$1:$A$100,"PINHEIRO DA CUNHA ESF",mai!$D$1:$D$100)+SUMIF(mai!$A$1:$A$100,"ALZIRA BRANDAO",mai!$D$1:$D$100)+SUMIF(mai!$A$1:$A$100,"DONA DELFINA",mai!$D$1:$D$100) -> 18 | H29: =SUMIF(jun!$A$1:$A$100,"CATRAMBI I **",jun!$D$1:$D$100)+SUMIF(jun!$A$1:$A$100,"PINHEIRO DA CUNHA ESF",jun!$D$1:$D$100)+SUMIF(jun!$A$1:$A$100,"ALZIRA BRANDAO",jun!$D$1:$D$100)+SUMIF(jun!$A$1:$A$100,"DONA DELFINA",jun!$D$1:$D$100) -> 19 | I29: =SUMIF(jul!$A$1:$A$100,"CATRAMBI I **",jul!$D$1:$D$100)+SUMIF(jul!$A$1:$A$100,"PINHEIRO DA CUNHA ESF",jul!$D$1:$D$100)+SUMIF(jul!$A$1:$A$100,"ALZIRA BRANDAO",jul!$D$1:$D$100)+SUMIF(jul!$A$1:$A$100,"DONA DELFINA",jul!$D$1:$D$100) -> 20 | J29: =SUMIF(ago!$A$1:$A$100,"CATRAMBI I **",ago!$D$1:$D$100)+SUMIF(ago!$A$1:$A$100,"PINHEIRO DA CUNHA ESF",ago!$D$1:$D$100)+SUMIF(ago!$A$1:$A$100,"ALZIRA BRANDAO",ago!$D$1:$D$100)+SUMIF(ago!$A$1:$A$100,"DONA DELFINA",ago!$D$1:$D$100) -> 25 | K29: =SUMIF(set!$A$1:$A$100,"CATRAMBI I **",set!$D$1:$D$100)+SUMIF(set!$A$1:$A$100,"PINHEIRO DA CUNHA ESF",set!$D$1:$D$100)+SUMIF(set!$A$1:$A$100,"ALZIRA BRANDAO",set!$D$1:$D$100)+SUMIF(set!$A$1:$A$100,"DONA DELFINA",set!$D$1:$D$100) -> 0 | L29: =SUMIF(out!$A$1:$A$100,"CATRAMBI I **",out!$D$1:$D$100)+SUMIF(out!$A$1:$A$100,"PINHEIRO DA CUNHA ESF",out!$D$1:$D$100)+SUMIF(out!$A$1:$A$100,"ALZIRA BRANDAO",out!$D$1:$D$100)+SUMIF(out!$A$1:$A$100,"DONA DELFINA",out!$D$1:$D$100) -> 0 | M29: =SUMIF(nov!$A$1:$A$100,"CATRAMBI I **",nov!$D$1:$D$100)+SUMIF(nov!$A$1:$A$100,"PINHEIRO DA CUNHA ESF",nov!$D$1:$D$100)+SUMIF(nov!$A$1:$A$100,"ALZIRA BRANDAO",nov!$D$1:$D$100)+SUMIF(nov!$A$1:$A$100,"DONA DELFINA",nov!$D$1:$D$100) -> 0 | N29: =SUMIF(dez!$A$1:$A$100,"CATRAMBI I **",dez!$D$1:$D$100)+SUMIF(dez!$A$1:$A$100,"PINHEIRO DA CUNHA ESF",dez!$D$1:$D$100)+SUMIF(dez!$A$1:$A$100,"ALZIRA BRANDAO",dez!$D$1:$D$100)+SUMIF(dez!$A$1:$A$100,"DONA DELFINA",dez!$D$1:$D$100) -> 0 | O29: =C29+D29+E29 -> 96 | P29: =F29+G29+H29 -> 59 | Q29: =I29+J29+K29 -> 45 | R29: =L29+M29+N29 -> 0 | S29: =C29+D29+E29 -> 96
B30: SABOIA LIMA ESB | C30: =SUMIF(jan!$A$1:$A$94,"SABOIA LIMA I",jan!$D$1:$D$100)+SUMIF(jan!$A$1:$A$94,"SABOIA LIMA II",jan!$D$1:$D$100)+SUMIF(jan!$A$1:$A$94,"SABOIA LIMA III",jan!$D$1:$D$100)+SUMIF(jan!$A$1:$A$94,"XAVIER DE BRITO",jan!$D$1:$D$100)+SUMIF(jan!$A$1:$A$94,"MARIA AMALIA ESF",jan!$D$1:$D$100) -> 21 | D30: =SUMIF(fev!$A$1:$A$100,"SABOIA LIMA I **",fev!$D$1:$D$100)+SUMIF(fev!$A$1:$A$100,"XAVIER DE BRITO",fev!$D$1:$D$100)+SUMIF(fev!$A$1:$A$100,"MARIA AMALIA ESF",fev!$D$1:$D$100) -> 21 | E30: =SUMIF(mar!$A$1:$A$100,"SABOIA LIMA I **",mar!$D$1:$D$100)+SUMIF(mar!$A$1:$A$100,"XAVIER DE BRITO",mar!$D$1:$D$100)+SUMIF(mar!$A$1:$A$100,"MARIA AMALIA ESF",mar!$D$1:$D$100) -> 21 | F30: =SUMIF(abr!$A$1:$A$100,"SABOIA LIMA I **",abr!$D$1:$D$100)+SUMIF(abr!$A$1:$A$100,"XAVIER DE BRITO",abr!$D$1:$D$100)+SUMIF(abr!$A$1:$A$100,"MARIA AMALIA ESF",abr!$D$1:$D$100) -> 23 | G30: =SUMIF(mai!$A$1:$A$100,"SABOIA LIMA I **",mai!$D$1:$D$100)+SUMIF(mai!$A$1:$A$100,"XAVIER DE BRITO",mai!$D$1:$D$100)+SUMIF(mai!$A$1:$A$100,"MARIA AMALIA ESF",mai!$D$1:$D$100) -> 22 | H30: =SUMIF(jun!$A$1:$A$100,"SABOIA LIMA I **",jun!$D$1:$D$100)+SUMIF(jun!$A$1:$A$100,"XAVIER DE BRITO",jun!$D$1:$D$100)+SUMIF(jun!$A$1:$A$100,"MARIA AMALIA ESF",jun!$D$1:$D$100) -> 22 | I30: =SUMIF(jul!$A$1:$A$100,"SABOIA LIMA I **",jul!$D$1:$D$100)+SUMIF(jul!$A$1:$A$100,"XAVIER DE BRITO",jul!$D$1:$D$100)+SUMIF(jul!$A$1:$A$100,"MARIA AMALIA ESF",jul!$D$1:$D$100) -> 23 | J30: =SUMIF(ago!$A$1:$A$100,"SABOIA LIMA I **",ago!$D$1:$D$100)+SUMIF(ago!$A$1:$A$100,"XAVIER DE BRITO",ago!$D$1:$D$100)+SUMIF(ago!$A$1:$A$100,"MARIA AMALIA ESF",ago!$D$1:$D$100) -> 21 | K30: =SUMIF(set!$A$1:$A$100,"SABOIA LIMA I **",set!$D$1:$D$100)+SUMIF(set!$A$1:$A$100,"XAVIER DE BRITO",set!$D$1:$D$100)+SUMIF(set!$A$1:$A$100,"MARIA AMALIA ESF",set!$D$1:$D$100) -> 0 | L30: =SUMIF(out!$A$1:$A$100,"SABOIA LIMA I **",out!$D$1:$D$100)+SUMIF(out!$A$1:$A$100,"XAVIER DE BRITO",out!$D$1:$D$100)+SUMIF(out!$A$1:$A$100,"MARIA AMALIA ESF",out!$D$1:$D$100) -> 0 | M30: =SUMIF(nov!$A$1:$A$100,"SABOIA LIMA I **",nov!$D$1:$D$100)+SUMIF(nov!$A$1:$A$100,"XAVIER DE BRITO",nov!$D$1:$D$100)+SUMIF(nov!$A$1:$A$100,"MARIA AMALIA ESF",nov!$D$1:$D$100) -> 0 | N30: =SUMIF(dez!$A$1:$A$100,"SABOIA LIMA I **",dez!$D$1:$D$100)+SUMIF(dez!$A$1:$A$100,"XAVIER DE BRITO",dez!$D$1:$D$100)+SUMIF(dez!$A$1:$A$100,"MARIA AMALIA ESF",dez!$D$1:$D$100) -> 0 | O30: =C30+D30+E30 -> 63 | P30: =F30+G30+H30 -> 67 | Q30: =I30+J30+K30 -> 44 | R30: =L30+M30+N30 -> 0 | S30: =C30+D30+E30 -> 63
A31: CMS HÉLIO PELLEGRINO | B31: VILLA LOBOS ESB | C31: =SUMIF(jan!$A$1:$A$100,"VILLA LOBOS",jan!$D$1:$D$100)+SUMIF(jan!$A$1:$A$100,"AFONSO PENA",jan!$D$1:$D$100)+SUMIF(jan!$A$1:$A$100,"CAPUCHINHOS",jan!$D$1:$D$100) -> 33 | D31: =SUMIF(fev!$A$1:$A$100,"VILLA LOBOS",fev!$D$1:$D$100)+SUMIF(fev!$A$1:$A$100,"AFONSO PENA",fev!$D$1:$D$100)+SUMIF(fev!$A$1:$A$100,"CAPUCHINHOS",fev!$D$1:$D$100) -> 38 | E31: =SUMIF(mar!$A$1:$A$100,"VILLA LOBOS",mar!$D$1:$D$100)+SUMIF(mar!$A$1:$A$100,"AFONSO PENA",mar!$D$1:$D$100)+SUMIF(mar!$A$1:$A$100,"CAPUCHINHOS",mar!$D$1:$D$100) -> 38 | F31: =SUMIF(abr!$A$1:$A$100,"VILLA LOBOS",abr!$D$1:$D$100)+SUMIF(abr!$A$1:$A$100,"AFONSO PENA",abr!$D$1:$D$100)+SUMIF(abr!$A$1:$A$100,"CAPUCHINHOS",abr!$D$1:$D$100) -> 38 | G31: =SUMIF(mai!$A$1:$A$100,"VILLA LOBOS",mai!$D$1:$D$100)+SUMIF(mai!$A$1:$A$100,"AFONSO PENA",mai!$D$1:$D$100)+SUMIF(mai!$A$1:$A$100,"CAPUCHINHOS",mai!$D$1:$D$100) -> 40 | H31: =SUMIF(jun!$A$1:$A$100,"VILLA LOBOS",jun!$D$1:$D$100)+SUMIF(jun!$A$1:$A$100,"AFONSO PENA",jun!$D$1:$D$100)+SUMIF(jun!$A$1:$A$100,"CAPUCHINHOS",jun!$D$1:$D$100) -> 37 | I31: =SUMIF(jul!$A$1:$A$100,"VILLA LOBOS",jul!$D$1:$D$100)+SUMIF(jul!$A$1:$A$100,"AFONSO PENA",jul!$D$1:$D$100)+SUMIF(jul!$A$1:$A$100,"CAPUCHINHOS",jul!$D$1:$D$100) -> 44 | J31: =SUMIF(ago!$A$1:$A$100,"VILLA LOBOS",ago!$D$1:$D$100)+SUMIF(ago!$A$1:$A$100,"AFONSO PENA",ago!$D$1:$D$100)+SUMIF(ago!$A$1:$A$100,"CAPUCHINHOS",ago!$D$1:$D$100) -> 48 | K31: =SUMIF(set!$A$1:$A$100,"VILLA LOBOS",set!$D$1:$D$100)+SUMIF(set!$A$1:$A$100,"AFONSO PENA",set!$D$1:$D$100)+SUMIF(set!$A$1:$A$100,"CAPUCHINHOS",set!$D$1:$D$100) -> 0 | L31: =SUMIF(out!$A$1:$A$100,"VILLA LOBOS",out!$D$1:$D$100)+SUMIF(out!$A$1:$A$100,"AFONSO PENA",out!$D$1:$D$100)+SUMIF(out!$A$1:$A$100,"CAPUCHINHOS",out!$D$1:$D$100) -> 0 | M31: =SUMIF(nov!$A$1:$A$100,"VILLA LOBOS",nov!$D$1:$D$100)+SUMIF(nov!$A$1:$A$100,"AFONSO PENA",nov!$D$1:$D$100)+SUMIF(nov!$A$1:$A$100,"CAPUCHINHOS",nov!$D$1:$D$100) -> 0 | N31: =SUMIF(dez!$A$1:$A$100,"VILLA LOBOS",dez!$D$1:$D$100)+SUMIF(dez!$A$1:$A$100,"AFONSO PENA",dez!$D$1:$D$100)+SUMIF(dez!$A$1:$A$100,"CAPUCHINHOS",dez!$D$1:$D$100) -> 0 | O31: =C31+D31+E31 -> 109 | P31: =F31+G31+H31 -> 115 | Q31: =I31+J31+K31 -> 92 | R31: =L31+M31+N31 -> 0
B32: PRACA DA BANDEIRA ESB 1 | C32: =SUMIF(jan!$A$1:$A$100,"SENADOR FURTADO ESF",jan!$D$1:$D$100)+SUMIF(jan!$A$1:$A$100,"MARIZ E BARROS ESF",jan!$D$1:$D$100)+SUMIF(jan!$A$1:$A$100,"MARACANA",jan!$D$1:$D$100) -> 72 | D32: =SUMIF(fev!$A$1:$A$100,"SENADOR FURTADO ESF",fev!$D$1:$D$100)+SUMIF(fev!$A$1:$A$100,"MARIZ E BARROS ESF",fev!$D$1:$D$100)+SUMIF(fev!$A$1:$A$100,"MARACANA",fev!$D$1:$D$100) -> 75 | E32: =SUMIF(mar!$A$1:$A$100,"SENADOR FURTADO ESF",mar!$D$1:$D$100)+SUMIF(mar!$A$1:$A$100,"MARIZ E BARROS ESF",mar!$D$1:$D$100)+SUMIF(mar!$A$1:$A$100,"MARACANA",mar!$D$1:$D$100) -> 73 | F32: =SUMIF(abr!$A$1:$A$100,"SENADOR FURTADO ESF",abr!$D$1:$D$100)+SUMIF(abr!$A$1:$A$100,"MARIZ E BARROS ESF",abr!$D$1:$D$100)+SUMIF(abr!$A$1:$A$100,"MARACANA",abr!$D$1:$D$100) -> 76 | G32: =SUMIF(mai!$A$1:$A$100,"SENADOR FURTADO ESF",mai!$D$1:$D$100)+SUMIF(mai!$A$1:$A$100,"MARIZ E BARROS ESF",mai!$D$1:$D$100)+SUMIF(mai!$A$1:$A$100,"MARACANA",mai!$D$1:$D$100) -> 82 | H32: =SUMIF(jun!$A$1:$A$100,"SENADOR FURTADO ESF",jun!$D$1:$D$100)+SUMIF(jun!$A$1:$A$100,"MARIZ E BARROS ESF",jun!$D$1:$D$100)+SUMIF(jun!$A$1:$A$100,"MARACANA",jun!$D$1:$D$100) -> 85 | I32: =SUMIF(jul!$A$1:$A$100,"SENADOR FURTADO ESF",jul!$D$1:$D$100)+SUMIF(jul!$A$1:$A$100,"MARIZ E BARROS ESF",jul!$D$1:$D$100)+SUMIF(jul!$A$1:$A$100,"MARACANA",jul!$D$1:$D$100) -> 83 | J32: =SUMIF(ago!$A$1:$A$100,"SENADOR FURTADO ESF",ago!$D$1:$D$100)+SUMIF(ago!$A$1:$A$100,"MARIZ E BARROS ESF",ago!$D$1:$D$100)+SUMIF(ago!$A$1:$A$100,"MARACANA",ago!$D$1:$D$100) -> 82 | K32: =SUMIF(set!$A$1:$A$100,"SENADOR FURTADO ESF",set!$D$1:$D$100)+SUMIF(set!$A$1:$A$100,"MARIZ E BARROS ESF",set!$D$1:$D$100)+SUMIF(set!$A$1:$A$100,"MARACANA",set!$D$1:$D$100) -> 0 | L32: =SUMIF(out!$A$1:$A$100,"SENADOR FURTADO ESF",out!$D$1:$D$100)+SUMIF(out!$A$1:$A$100,"MARIZ E BARROS ESF",out!$D$1:$D$100)+SUMIF(out!$A$1:$A$100,"MARACANA",out!$D$1:$D$100) -> 0 | M32: =SUMIF(nov!$A$1:$A$100,"SENADOR FURTADO ESF",nov!$D$1:$D$100)+SUMIF(nov!$A$1:$A$100,"MARIZ E BARROS ESF",nov!$D$1:$D$100)+SUMIF(nov!$A$1:$A$100,"MARACANA",nov!$D$1:$D$100) -> 0 | N32: =SUMIF(dez!$A$1:$A$100,"SENADOR FURTADO ESF",dez!$D$1:$D$100)+SUMIF(dez!$A$1:$A$100,"MARIZ E BARROS ESF",dez!$D$1:$D$100)+SUMIF(dez!$A$1:$A$100,"MARACANA",dez!$D$1:$D$100) -> 0 | O32: =C32+D32+E32 -> 220 | P32: =F32+G32+H32 -> 243 | Q32: =I32+J32+K32 -> 165 | R32: =L32+M32+N32 -> 0
B33: BANDEIRA ESB | C33: =SUMIF(jan!$A$1:$A$100,"BANDEIRA I",jan!$D$1:$D$100)+SUMIF(jan!$A$1:$A$100,"BANDEIRA II",jan!$D$1:$D$100)+SUMIF(jan!$A$1:$A$100,"BANDEIRA III",jan!$D$1:$D$100)+SUMIF(jan!$A$1:$A$100,"MATOSO I",jan!$D$1:$D$100)+SUMIF(jan!$A$1:$A$100,"MATOSO II",jan!$D$1:$D$100)+SUMIF(jan!$A$1:$A$100,"MATOSO III",jan!$D$1:$D$100)+SUMIF(jan!$A$1:$A$100,"CANABARRO",jan!$D$1:$D$100) -> 187 | D33: =SUMIF(fev!$A$1:$A$100,"BANDEIRA I",fev!$D$1:$D$100)+SUMIF(fev!$A$1:$A$100,"BANDEIRA II",fev!$D$1:$D$100)+SUMIF(fev!$A$1:$A$100,"BANDEIRA III",fev!$D$1:$D$100)+SUMIF(fev!$A$1:$A$100,"MATOSO I",fev!$D$1:$D$100)+SUMIF(fev!$A$1:$A$100,"MATOSO II",fev!$D$1:$D$100)+SUMIF(fev!$A$1:$A$100,"MATOSO III",fev!$D$1:$D$100)+SUMIF(fev!$A$1:$A$100,"CANABARRO",fev!$D$1:$D$100) -> 188 | E33: =SUMIF(mar!$A$1:$A$100,"BANDEIRA I",mar!$D$1:$D$100)+SUMIF(mar!$A$1:$A$100,"BANDEIRA II",mar!$D$1:$D$100)+SUMIF(mar!$A$1:$A$100,"BANDEIRA III",mar!$D$1:$D$100)+SUMIF(mar!$A$1:$A$100,"MATOSO I",mar!$D$1:$D$100)+SUMIF(mar!$A$1:$A$100,"MATOSO II",mar!$D$1:$D$100)+SUMIF(mar!$A$1:$A$100,"MATOSO III",mar!$D$1:$D$100)+SUMIF(mar!$A$1:$A$100,"CANABARRO",mar!$D$1:$D$100) -> 186 | F33: =SUMIF(abr!$A$1:$A$100,"BANDEIRA I",abr!$D$1:$D$100)+SUMIF(abr!$A$1:$A$100,"BANDEIRA II",abr!$D$1:$D$100)+SUMIF(abr!$A$1:$A$100,"BANDEIRA III",abr!$D$1:$D$100)+SUMIF(abr!$A$1:$A$100,"MATOSO I",abr!$D$1:$D$100)+SUMIF(abr!$A$1:$A$100,"MATOSO II",abr!$D$1:$D$100)+SUMIF(abr!$A$1:$A$100,"MATOSO III",abr!$D$1:$D$100)+SUMIF(abr!$A$1:$A$100,"CANABARRO",abr!$D$1:$D$100) -> 183 | G33: =SUMIF(mai!$A$1:$A$100,"BANDEIRA I",mai!$D$1:$D$100)+SUMIF(mai!$A$1:$A$100,"BANDEIRA II",mai!$D$1:$D$100)+SUMIF(mai!$A$1:$A$100,"BANDEIRA III",mai!$D$1:$D$100)+SUMIF(mai!$A$1:$A$100,"MATOSO I",mai!$D$1:$D$100)+SUMIF(mai!$A$1:$A$100,"MATOSO II",mai!$D$1:$D$100)+SUMIF(mai!$A$1:$A$100,"MATOSO III",mai!$D$1:$D$100)+SUMIF(mai!$A$1:$A$100,"CANABARRO",mai!$D$1:$D$100) -> 147 | H33: =SUMIF(jun!$A$1:$A$100,"BANDEIRA I",jun!$D$1:$D$100)+SUMIF(jun!$A$1:$A$100,"BANDEIRA II",jun!$D$1:$D$100)+SUMIF(jun!$A$1:$A$100,"BANDEIRA III",jun!$D$1:$D$100)+SUMIF(jun!$A$1:$A$100,"MATOSO I",jun!$D$1:$D$100)+SUMIF(jun!$A$1:$A$100,"MATOSO II",jun!$D$1:$D$100)+SUMIF(jun!$A$1:$A$100,"MATOSO III",jun!$D$1:$D$100)+SUMIF(jun!$A$1:$A$100,"CANABARRO",jun!$D$1:$D$100) -> 125 | I33: =SUMIF(jul!$A$1:$A$100,"BANDEIRA I",jul!$D$1:$D$100)+SUMIF(jul!$A$1:$A$100,"BANDEIRA II",jul!$D$1:$D$100)+SUMIF(jul!$A$1:$A$100,"BANDEIRA III",jul!$D$1:$D$100)+SUMIF(jul!$A$1:$A$100,"MATOSO I",jul!$D$1:$D$100)+SUMIF(jul!$A$1:$A$100,"MATOSO II",jul!$D$1:$D$100)+SUMIF(jul!$A$1:$A$100,"MATOSO III",jul!$D$1:$D$100)+SUMIF(jul!$A$1:$A$100,"CANABARRO",jul!$D$1:$D$100) -> 113 | J33: =SUMIF(ago!$A$1:$A$100,"BANDEIRA I",ago!$D$1:$D$100)+SUMIF(ago!$A$1:$A$100,"BANDEIRA II",ago!$D$1:$D$100)+SUMIF(ago!$A$1:$A$100,"BANDEIRA III",ago!$D$1:$D$100)+SUMIF(ago!$A$1:$A$100,"MATOSO I",ago!$D$1:$D$100)+SUMIF(ago!$A$1:$A$100,"MATOSO II",ago!$D$1:$D$100)+SUMIF(ago!$A$1:$A$100,"MATOSO III",ago!$D$1:$D$100)+SUMIF(ago!$A$1:$A$100,"CANABARRO",ago!$D$1:$D$100) -> 110 | K33: =SUMIF(set!$A$1:$A$100,"BANDEIRA I",set!$D$1:$D$100)+SUMIF(set!$A$1:$A$100,"BANDEIRA II",set!$D$1:$D$100)+SUMIF(set!$A$1:$A$100,"BANDEIRA III",set!$D$1:$D$100)+SUMIF(set!$A$1:$A$100,"MATOSO I",set!$D$1:$D$100)+SUMIF(set!$A$1:$A$100,"MATOSO II",set!$D$1:$D$100)+SUMIF(set!$A$1:$A$100,"MATOSO III",set!$D$1:$D$100)+SUMIF(set!$A$1:$A$100,"CANABARRO",set!$D$1:$D$100) -> 0 | L33: =SUMIF(out!$A$1:$A$100,"BANDEIRA I",out!$D$1:$D$100)+SUMIF(out!$A$1:$A$100,"BANDEIRA II",out!$D$1:$D$100)+SUMIF(out!$A$1:$A$100,"BANDEIRA III",out!$D$1:$D$100)+SUMIF(out!$A$1:$A$100,"MATOSO I",out!$D$1:$D$100)+SUMIF(out!$A$1:$A$100,"MATOSO II",out!$D$1:$D$100)+SUMIF(out!$A$1:$A$100,"MATOSO III",out!$D$1:$D$100)+SUMIF(out!$A$1:$A$100,"CANABARRO",out!$D$1:$D$100) -> 0 | M33: =SUMIF(nov!$A$1:$A$100,"BANDEIRA I",nov!$D$1:$D$100)+SUMIF(nov!$A$1:$A$100,"BANDEIRA II",nov!$D$1:$D$100)+SUMIF(nov!$A$1:$A$100,"BANDEIRA III",nov!$D$1:$D$100)+SUMIF(nov!$A$1:$A$100,"MATOSO I",nov!$D$1:$D$100)+SUMIF(nov!$A$1:$A$100,"MATOSO II",nov!$D$1:$D$100)+SUMIF(nov!$A$1:$A$100,"MATOSO III",nov!$D$1:$D$100)+SUMIF(nov!$A$1:$A$100,"CANABARRO",nov!$D$1:$D$100) -> 0 | N33: =SUMIF(dez!$A$1:$A$100,"BANDEIRA I",dez!$D$1:$D$100)+SUMIF(dez!$A$1:$A$100,"BANDEIRA II",dez!$D$1:$D$100)+SUMIF(dez!$A$1:$A$100,"BANDEIRA III",dez!$D$1:$D$100)+SUMIF(dez!$A$1:$A$100,"MATOSO I",dez!$D$1:$D$100)+SUMIF(dez!$A$1:$A$100,"MATOSO II",dez!$D$1:$D$100)+SUMIF(dez!$A$1:$A$100,"MATOSO III",dez!$D$1:$D$100)+SUMIF(dez!$A$1:$A$100,"CANABARRO",dez!$D$1:$D$100) -> 0 | O33: =C33+D33+E33 -> 561 | P33: =F33+G33+H33 -> 455 | Q33: =I33+J33+K33 -> 223 | R33: =L33+M33+N33 -> 0
A34: CMS MARIA AUGUSTA ESTRELLA | B34: SENADOR ESB | C34: =SUMIF(jan!$A$1:$A$100,"SENADOR",jan!$D$1:$D$100)+SUMIF(jan!$A$1:$A$100,"BARAO DE COTEGIPE",jan!$D$1:$D$100)+SUMIF(jan!$A$1:$A$100,"PETROCOCHINO",jan!$D$1:$D$100)+SUMIF(jan!$A$1:$A$100,"SANTA ISABEL",jan!$D$1:$D$100) -> 48 | D34: =SUMIF(fev!$A$1:$A$100,"SENADOR",fev!$D$1:$D$100)+SUMIF(fev!$A$1:$A$100,"BARAO DE COTEGIPE",fev!$D$1:$D$100)+SUMIF(fev!$A$1:$A$100,"PETROCOCHINO",fev!$D$1:$D$100)+SUMIF(fev!$A$1:$A$100,"SANTA ISABEL",fev!$D$1:$D$100) -> 48 | E34: =SUMIF(mar!$A$1:$A$100,"SENADOR",mar!$D$1:$D$100)+SUMIF(mar!$A$1:$A$100,"BARAO DE COTEGIPE",mar!$D$1:$D$100)+SUMIF(mar!$A$1:$A$100,"PETROCOCHINO",mar!$D$1:$D$100)+SUMIF(mar!$A$1:$A$100,"SANTA ISABEL",mar!$D$1:$D$100) -> 52 | F34: =SUMIF(abr!$A$1:$A$100,"SENADOR",abr!$D$1:$D$100)+SUMIF(abr!$A$1:$A$100,"BARAO DE COTEGIPE",abr!$D$1:$D$100)+SUMIF(abr!$A$1:$A$100,"PETROCOCHINO",abr!$D$1:$D$100)+SUMIF(abr!$A$1:$A$100,"SANTA ISABEL",abr!$D$1:$D$100) -> 55 | G34: =SUMIF(mai!$A$1:$A$100,"SENADOR",mai!$D$1:$D$100)+SUMIF(mai!$A$1:$A$100,"BARAO DE COTEGIPE",mai!$D$1:$D$100)+SUMIF(mai!$A$1:$A$100,"PETROCOCHINO",mai!$D$1:$D$100)+SUMIF(mai!$A$1:$A$100,"SANTA ISABEL",mai!$D$1:$D$100) -> 59 | H34: =SUMIF(jun!$A$1:$A$100,"SENADOR",jun!$D$1:$D$100)+SUMIF(jun!$A$1:$A$100,"BARAO DE COTEGIPE",jun!$D$1:$D$100)+SUMIF(jun!$A$1:$A$100,"PETROCOCHINO",jun!$D$1:$D$100)+SUMIF(jun!$A$1:$A$100,"SANTA ISABEL",jun!$D$1:$D$100) -> 66 | I34: =SUMIF(jul!$A$1:$A$100,"SENADOR",jul!$D$1:$D$100)+SUMIF(jul!$A$1:$A$100,"BARAO DE COTEGIPE",jul!$D$1:$D$100)+SUMIF(jul!$A$1:$A$100,"PETROCOCHINO",jul!$D$1:$D$100)+SUMIF(jul!$A$1:$A$100,"SANTA ISABEL",jul!$D$1:$D$100) -> 69 | J34: =SUMIF(ago!$A$1:$A$100,"SENADOR",ago!$D$1:$D$100)+SUMIF(ago!$A$1:$A$100,"BARAO DE COTEGIPE",ago!$D$1:$D$100)+SUMIF(ago!$A$1:$A$100,"PETROCOCHINO",ago!$D$1:$D$100)+SUMIF(ago!$A$1:$A$100,"SANTA ISABEL",ago!$D$1:$D$100) -> 67 | K34: =SUMIF(set!$A$1:$A$100,"SENADOR",set!$D$1:$D$100)+SUMIF(set!$A$1:$A$100,"BARAO DE COTEGIPE",set!$D$1:$D$100)+SUMIF(set!$A$1:$A$100,"PETROCOCHINO",set!$D$1:$D$100)+SUMIF(set!$A$1:$A$100,"SANTA ISABEL",set!$D$1:$D$100) -> 0 | L34: =SUMIF(out!$A$1:$A$100,"SENADOR",out!$D$1:$D$100)+SUMIF(out!$A$1:$A$100,"BARAO DE COTEGIPE",out!$D$1:$D$100)+SUMIF(out!$A$1:$A$100,"PETROCOCHINO",out!$D$1:$D$100)+SUMIF(out!$A$1:$A$100,"SANTA ISABEL",out!$D$1:$D$100) -> 0 | M34: =SUMIF(nov!$A$1:$A$100,"SENADOR",nov!$D$1:$D$100)+SUMIF(nov!$A$1:$A$100,"BARAO DE COTEGIPE",nov!$D$1:$D$100)+SUMIF(nov!$A$1:$A$100,"PETROCOCHINO",nov!$D$1:$D$100)+SUMIF(nov!$A$1:$A$100,"SANTA ISABEL",nov!$D$1:$D$100) -> 0 | N34: =SUMIF(dez!$A$1:$A$100,"SENADOR",dez!$D$1:$D$100)+SUMIF(dez!$A$1:$A$100,"BARAO DE COTEGIPE",dez!$D$1:$D$100)+SUMIF(dez!$A$1:$A$100,"PETROCOCHINO",dez!$D$1:$D$100)+SUMIF(dez!$A$1:$A$100,"SANTA ISABEL",dez!$D$1:$D$100) -> 0 | O34: =C34+D34+E34 -> 148 | P34: =F34+G34+H34 -> 180 | Q34: =I34+J34+K34 -> 136 | R34: =L34+M34+N34 -> 0
B35: MIGUEL PEDRO ESB | C35: =SUMIF(jan!$A$1:$A$100,"MIGUEL PEDRO",jan!$D$1:$D$100)+SUMIF(jan!$A$1:$A$100,"MANOEL DE ABREU",jan!$D$1:$D$100)+SUMIF(jan!$A$1:$A$100,"VILA OPERARIA ESF",jan!$D$1:$D$100) -> 49 | D35: =SUMIF(fev!$A$1:$A$100,"MIGUEL PEDRO",fev!$D$1:$D$100)+SUMIF(fev!$A$1:$A$100,"MANOEL DE ABREU",fev!$D$1:$D$100)+SUMIF(fev!$A$1:$A$100,"VILA OPERARIA ESF",fev!$D$1:$D$100) -> 49 | E35: =SUMIF(mar!$A$1:$A$100,"MIGUEL PEDRO",mar!$D$1:$D$100)+SUMIF(mar!$A$1:$A$100,"MANOEL DE ABREU",mar!$D$1:$D$100)+SUMIF(mar!$A$1:$A$100,"VILA OPERARIA ESF",mar!$D$1:$D$100) -> 43 | F35: =SUMIF(abr!$A$1:$A$100,"MIGUEL PEDRO",abr!$D$1:$D$100)+SUMIF(abr!$A$1:$A$100,"MANOEL DE ABREU",abr!$D$1:$D$100)+SUMIF(abr!$A$1:$A$100,"VILA OPERARIA ESF",abr!$D$1:$D$100) -> 42 | G35: =SUMIF(mai!$A$1:$A$100,"MIGUEL PEDRO",mai!$D$1:$D$100)+SUMIF(mai!$A$1:$A$100,"MANOEL DE ABREU",mai!$D$1:$D$100)+SUMIF(mai!$A$1:$A$100,"VILA OPERARIA ESF",mai!$D$1:$D$100) -> 44 | H35: =SUMIF(jun!$A$1:$A$100,"MIGUEL PEDRO",jun!$D$1:$D$100)+SUMIF(jun!$A$1:$A$100,"MANOEL DE ABREU",jun!$D$1:$D$100)+SUMIF(jun!$A$1:$A$100,"VILA OPERARIA ESF",jun!$D$1:$D$100) -> 46 | I35: =SUMIF(jul!$A$1:$A$100,"MIGUEL PEDRO",jul!$D$1:$D$100)+SUMIF(jul!$A$1:$A$100,"MANOEL DE ABREU",jul!$D$1:$D$100)+SUMIF(jul!$A$1:$A$100,"VILA OPERARIA ESF",jul!$D$1:$D$100) -> 52 | J35: =SUMIF(ago!$A$1:$A$100,"MIGUEL PEDRO",ago!$D$1:$D$100)+SUMIF(ago!$A$1:$A$100,"MANOEL DE ABREU",ago!$D$1:$D$100)+SUMIF(ago!$A$1:$A$100,"VILA OPERARIA ESF",ago!$D$1:$D$100) -> 61 | K35: =SUMIF(set!$A$1:$A$100,"MIGUEL PEDRO",set!$D$1:$D$100)+SUMIF(set!$A$1:$A$100,"MANOEL DE ABREU",set!$D$1:$D$100)+SUMIF(set!$A$1:$A$100,"VILA OPERARIA ESF",set!$D$1:$D$100) -> 0 | L35: =SUMIF(out!$A$1:$A$100,"MIGUEL PEDRO",out!$D$1:$D$100)+SUMIF(out!$A$1:$A$100,"MANOEL DE ABREU",out!$D$1:$D$100)+SUMIF(out!$A$1:$A$100,"VILA OPERARIA ESF",out!$D$1:$D$100) -> 0 | M35: =SUMIF(nov!$A$1:$A$100,"MIGUEL PEDRO",nov!$D$1:$D$100)+SUMIF(nov!$A$1:$A$100,"MANOEL DE ABREU",nov!$D$1:$D$100)+SUMIF(nov!$A$1:$A$100,"VILA OPERARIA ESF",nov!$D$1:$D$100) -> 0 | N35: =SUMIF(dez!$A$1:$A$100,"MIGUEL PEDRO",dez!$D$1:$D$100)+SUMIF(dez!$A$1:$A$100,"MANOEL DE ABREU",dez!$D$1:$D$100)+SUMIF(dez!$A$1:$A$100,"VILA OPERARIA ESF",dez!$D$1:$D$100) -> 0 | O35: =C35+D35+E35 -> 141 | P35: =F35+G35+H35 -> 132 | Q35: =I35+J35+K35 -> 113 | R35: =L35+M35+N35 -> 0
B36: CONSELHEIRO ESB | C36: =SUMIF(jan!$A$1:$A$100,"CONSELHEIRO",jan!$D$1:$D$100)+SUMIF(jan!$A$1:$A$100,"SOUZA FRANCO",jan!$D$1:$D$100)+SUMIF(jan!$A$1:$A$100,"VIA LACTEA",jan!$D$1:$D$100) -> 52 | D36: =SUMIF(fev!$A$1:$A$100,"CONSELHEIRO",fev!$D$1:$D$100)+SUMIF(fev!$A$1:$A$100,"SOUZA FRANCO",fev!$D$1:$D$100)+SUMIF(fev!$A$1:$A$100,"VIA LACTEA",fev!$D$1:$D$100) -> 48 | E36: =SUMIF(mar!$A$1:$A$100,"CONSELHEIRO",mar!$D$1:$D$100)+SUMIF(mar!$A$1:$A$100,"SOUZA FRANCO",mar!$D$1:$D$100)+SUMIF(mar!$A$1:$A$100,"VIA LACTEA",mar!$D$1:$D$100) -> 53 | F36: =SUMIF(abr!$A$1:$A$100,"CONSELHEIRO",abr!$D$1:$D$100)+SUMIF(abr!$A$1:$A$100,"SOUZA FRANCO",abr!$D$1:$D$100)+SUMIF(abr!$A$1:$A$100,"VIA LACTEA",abr!$D$1:$D$100) -> 57 | G36: =SUMIF(mai!$A$1:$A$100,"CONSELHEIRO",mai!$D$1:$D$100)+SUMIF(mai!$A$1:$A$100,"SOUZA FRANCO",mai!$D$1:$D$100)+SUMIF(mai!$A$1:$A$100,"VIA LACTEA",mai!$D$1:$D$100) -> 60 | H36: =SUMIF(jun!$A$1:$A$100,"CONSELHEIRO",jun!$D$1:$D$100)+SUMIF(jun!$A$1:$A$100,"SOUZA FRANCO",jun!$D$1:$D$100)+SUMIF(jun!$A$1:$A$100,"VIA LACTEA",jun!$D$1:$D$100) -> 64 | I36: =SUMIF(jul!$A$1:$A$100,"CONSELHEIRO",jul!$D$1:$D$100)+SUMIF(jul!$A$1:$A$100,"SOUZA FRANCO",jul!$D$1:$D$100)+SUMIF(jul!$A$1:$A$100,"VIA LACTEA",jul!$D$1:$D$100) -> 66 | J36: =SUMIF(ago!$A$1:$A$100,"CONSELHEIRO",ago!$D$1:$D$100)+SUMIF(ago!$A$1:$A$100,"SOUZA FRANCO",ago!$D$1:$D$100)+SUMIF(ago!$A$1:$A$100,"VIA LACTEA",ago!$D$1:$D$100) -> 67 | K36: =SUMIF(set!$A$1:$A$100,"CONSELHEIRO",set!$D$1:$D$100)+SUMIF(set!$A$1:$A$100,"SOUZA FRANCO",set!$D$1:$D$100)+SUMIF(set!$A$1:$A$100,"VIA LACTEA",set!$D$1:$D$100) -> 0 | L36: =SUMIF(out!$A$1:$A$100,"CONSELHEIRO",out!$D$1:$D$100)+SUMIF(out!$A$1:$A$100,"SOUZA FRANCO",out!$D$1:$D$100)+SUMIF(out!$A$1:$A$100,"VIA LACTEA",out!$D$1:$D$100) -> 0 | M36: =SUMIF(nov!$A$1:$A$100,"CONSELHEIRO",nov!$D$1:$D$100)+SUMIF(nov!$A$1:$A$100,"SOUZA FRANCO",nov!$D$1:$D$100)+SUMIF(nov!$A$1:$A$100,"VIA LACTEA",nov!$D$1:$D$100) -> 0 | N36: =SUMIF(dez!$A$1:$A$100,"CONSELHEIRO",dez!$D$1:$D$100)+SUMIF(dez!$A$1:$A$100,"SOUZA FRANCO",dez!$D$1:$D$100)+SUMIF(dez!$A$1:$A$100,"VIA LACTEA",dez!$D$1:$D$100) -> 0 | O36: =C36+D36+E36 -> 153 | P36: =F36+G36+H36 -> 181 | Q36: =I36+J36+K36 -> 133 | R36: =L36+M36+N36 -> 0
A37: CMS NICOLA ALBANO | B37: BOA VISTA ESB | C37: =SUMIF(jan!$A$1:$A$100,"BOA VISTA",jan!$D$1:$D$100)+SUMIF(jan!$A$1:$A$100,"FLORESTA DA TIJUCA",jan!$D$1:$D$100)+SUMIF(jan!$A$1:$A$100,"CACHOEIRA",jan!$D$1:$D$100) -> 57 | D37: =SUMIF(fev!$A$1:$A$100,"BOA VISTA",fev!$D$1:$D$100)+SUMIF(fev!$A$1:$A$100,"FLORESTA DA TIJUCA",fev!$D$1:$D$100)+SUMIF(fev!$A$1:$A$100,"CACHOEIRA",fev!$D$1:$D$100) -> 62 | E37: =SUMIF(mar!$A$1:$A$100,"BOA VISTA",mar!$D$1:$D$100)+SUMIF(mar!$A$1:$A$100,"FLORESTA DA TIJUCA",mar!$D$1:$D$100)+SUMIF(mar!$A$1:$A$100,"CACHOEIRA",mar!$D$1:$D$100) -> 73 | F37: =SUMIF(abr!$A$1:$A$100,"BOA VISTA",abr!$D$1:$D$100)+SUMIF(abr!$A$1:$A$100,"FLORESTA DA TIJUCA",abr!$D$1:$D$100)+SUMIF(abr!$A$1:$A$100,"CACHOEIRA",abr!$D$1:$D$100) -> 76 | G37: =SUMIF(mai!$A$1:$A$100,"BOA VISTA",mai!$D$1:$D$100)+SUMIF(mai!$A$1:$A$100,"FLORESTA DA TIJUCA",mai!$D$1:$D$100)+SUMIF(mai!$A$1:$A$100,"CACHOEIRA",mai!$D$1:$D$100) -> 86 | H37: =SUMIF(jun!$A$1:$A$100,"BOA VISTA",jun!$D$1:$D$100)+SUMIF(jun!$A$1:$A$100,"FLORESTA DA TIJUCA",jun!$D$1:$D$100)+SUMIF(jun!$A$1:$A$100,"CACHOEIRA",jun!$D$1:$D$100) -> 79 | I37: =SUMIF(jul!$A$1:$A$100,"BOA VISTA",jul!$D$1:$D$100)+SUMIF(jul!$A$1:$A$100,"FLORESTA DA TIJUCA",jul!$D$1:$D$100)+SUMIF(jul!$A$1:$A$100,"CACHOEIRA",jul!$D$1:$D$100) -> 94 | J37: =SUMIF(ago!$A$1:$A$100,"BOA VISTA",ago!$D$1:$D$100)+SUMIF(ago!$A$1:$A$100,"FLORESTA DA TIJUCA",ago!$D$1:$D$100)+SUMIF(ago!$A$1:$A$100,"CACHOEIRA",ago!$D$1:$D$100) -> 103 | K37: =SUMIF(set!$A$1:$A$100,"BOA VISTA",set!$D$1:$D$100)+SUMIF(set!$A$1:$A$100,"FLORESTA DA TIJUCA",set!$D$1:$D$100)+SUMIF(set!$A$1:$A$100,"CACHOEIRA",set!$D$1:$D$100) -> 0 | L37: =SUMIF(out!$A$1:$A$100,"BOA VISTA",out!$D$1:$D$100)+SUMIF(out!$A$1:$A$100,"FLORESTA DA TIJUCA",out!$D$1:$D$100)+SUMIF(out!$A$1:$A$100,"CACHOEIRA",out!$D$1:$D$100) -> 0 | M37: =SUMIF(nov!$A$1:$A$100,"BOA VISTA",nov!$D$1:$D$100)+SUMIF(nov!$A$1:$A$100,"FLORESTA DA TIJUCA",nov!$D$1:$D$100)+SUMIF(nov!$A$1:$A$100,"CACHOEIRA",nov!$D$1:$D$100) -> 0 | N37: =SUMIF(dez!$A$1:$A$100,"BOA VISTA",dez!$D$1:$D$100)+SUMIF(dez!$A$1:$A$100,"FLORESTA DA TIJUCA",dez!$D$1:$D$100)+SUMIF(dez!$A$1:$A$100,"CACHOEIRA",dez!$D$1:$D$100) -> 0 | O37: =C37+D37+E37 -> 192 | P37: =F37+G37+H37 -> 241 | Q37: =I37+J37+K37 -> 197 | R37: =L37+M37+N37 -> 0
A38: CMS NILZA ROSA | B38: RAIA ESB | C38: =SUMIF(jan!$A$1:$A$100,"RAIA",jan!$D$1:$D$100)+SUMIF(jan!$A$1:$A$100,"CASCATA",jan!$D$1:$D$100) -> 57 | D38: =SUMIF(fev!$A$1:$A$100,"RAIA",fev!$D$1:$D$100)+SUMIF(fev!$A$1:$A$100,"CASCATA",fev!$D$1:$D$100) -> 58 | E38: =SUMIF(mar!$A$1:$A$100,"RAIA",mar!$D$1:$D$100)+SUMIF(mar!$A$1:$A$100,"CASCATA",mar!$D$1:$D$100) -> 61 | F38: =SUMIF(abr!$A$1:$A$100,"RAIA",abr!$D$1:$D$100)+SUMIF(abr!$A$1:$A$100,"CASCATA",abr!$D$1:$D$100) -> 57 | G38: =SUMIF(mai!$A$1:$A$100,"RAIA",mai!$D$1:$D$100)+SUMIF(mai!$A$1:$A$100,"CASCATA",mai!$D$1:$D$100) -> 59 | H38: =SUMIF(jun!$A$1:$A$100,"RAIA",jun!$D$1:$D$100)+SUMIF(jun!$A$1:$A$100,"CASCATA",jun!$D$1:$D$100) -> 62 | I38: =SUMIF(jul!$A$1:$A$100,"RAIA",jul!$D$1:$D$100)+SUMIF(jul!$A$1:$A$100,"CASCATA",jul!$D$1:$D$100) -> 63 | J38: =SUMIF(ago!$A$1:$A$100,"RAIA",ago!$D$1:$D$100)+SUMIF(ago!$A$1:$A$100,"CASCATA",ago!$D$1:$D$100) -> 63 | K38: =SUMIF(set!$A$1:$A$100,"RAIA",set!$D$1:$D$100)+SUMIF(set!$A$1:$A$100,"CASCATA",set!$D$1:$D$100) -> 0 | L38: =SUMIF(out!$A$1:$A$100,"RAIA",out!$D$1:$D$100)+SUMIF(out!$A$1:$A$100,"CASCATA",out!$D$1:$D$100) -> 0 | M38: =SUMIF(nov!$A$1:$A$100,"RAIA",nov!$D$1:$D$100)+SUMIF(nov!$A$1:$A$100,"CASCATA",nov!$D$1:$D$100) -> 0 | N38: =SUMIF(dez!$A$1:$A$100,"RAIA",dez!$D$1:$D$100)+SUMIF(dez!$A$1:$A$100,"CASCATA",dez!$D$1:$D$100) -> 0 | O38: =C38+D38+E38 -> 176 | P38: =F38+G38+H38 -> 178 | Q38: =I38+J38+K38 -> 126 | R38: =L38+M38+N38 -> 0
A39: CAP 2.2 | C39: =SUMIF(jan!$A$1:$A$100,"*AP 22",jan!$D$1:$D$100) -> 1124 | D39: =SUMIF(fev!$A$1:$A$100,"*AP 22",fev!$D$1:$D$100) -> 1136 | E39: =SUMIF(mar!$A$1:$A$100,"*AP 22",mar!$D$1:$D$100) -> 1165 | F39: =SUMIF(abr!$A$1:$A$100,"*AP 22",abr!$D$1:$D$100) -> 1167 | G39: =SUMIF(mai!$A$1:$A$100,"*AP 22",mai!$D$1:$D$100) -> 1152 | H39: =SUMIF(jun!$A$1:$A$100,"*AP 22",jun!$D$1:$D$100) -> 1146 | I39: =SUMIF(jul!$A$1:$A$100,"*AP 22",jul!$D$1:$D$100) -> 1178 | J39: =SUMIF(ago!$A$1:$A$100,"*AP 22",ago!$D$1:$D$100) -> 1207 | K39: =SUMIF(set!$A$1:$A$100,"*AP 22",set!$D$1:$D$100) -> 0 | L39: =SUMIF(out!$A$1:$A$100,"*AP 22",out!$D$1:$D$100) -> 0 | M39: =SUMIF(nov!$A$1:$A$100,"*AP 22",nov!$D$1:$D$100) -> 0 | N39: =SUMIF(dez!$A$1:$A$100,"*AP 22",dez!$D$1:$D$100) -> 0 | O39: =C39+D39+E39 -> 3425 | P39: =F39+G39+H39 -> 3465 | Q39: =I39+J39+K39 -> 2385 | R39: =L39+M39+N39 -> 0
C40: =SUM(C18:C38) -> 1124 | D40: =SUM(D18:D38) -> 1136 | E40: =SUM(E18:E38) -> 1165 | F40: =SUM(F18:F38) -> 1167 | G40: =SUM(G18:G38) -> 1152 | H40: =SUM(H18:H38) -> 1146 | I40: =SUM(I18:I38) -> 1178 | J40: =SUM(J18:J38) -> 1207 | ... N40: =SUM(N18:N38) -> 0
A41: Denominador - PN encerrado
...

Sheet abr
A1: Secretaria Municipal de Saúde
A2: Saúde-Rio
A3: Clinica Padrao (0000000)
A5: Acompanhamento Anual De Uma Pessoa Tabagista (VAR3.G10_T.2023.0)
A6: Data: 01.04.2026 a 30.04.2026
A8: Area | B8: A (VAR3.G10_A.2023.0) | C8: B (VAR3.G10_B.2023.0) | D8: C (VAR3.G10_C.2023.0) | E8: D (VAR3.G10_D.2023.0) | F8: Total
A9: ANDARAI | B9: 0 | C9: 0 | D9: 0 | E9: 0 | F9: 0
A10: GASTAO PENALVA I | B10: 20 | C10: 0 | D10: 10 | E10: 20 | F10: 0
A11: GASTAO PENALVA II | B11: 2 | C11: 0 | D11: 0 | E11: 2 | F11: 0
A12: ITORORO | B12: 65 | C12: 0 | D12: 5 | E12: 65 | F12: 0
A13: SMS CF ANDARAI AP 22 | B13: 87 | C13: 0 | D13: 15 | E13: 87 | F13: 0
A14: ADOLFO CAMINHA | B14: 78 | C14: 0 | D14: 17 | E14: 78 | F14: 0
A15: ANDARAI | B15: 0 | C15: 0 | D15: 0 | E15: 0 | F15: 0
A16: ARAXA | B16: 56 | C16: 0 | D16: 8 | E16: 56 | F16: 0
A17: ESPERANCA | B17: 67 | C17: 0 | D17: 18 | E17: 67 | F17: 0
A18: FURNAS | B18: 51 | C18: 0 | D18: 10 | E18: 51 | F18: 0
A19: SANTO ESTEVAO | B19: 143 | C19: 0 | D19: 68 | E19: 143 | F19: 0
A20: UBERABA | B20: 72 | C20: 1 | D20: 25 | E20: 71 | F20: 0
